2015-07-23 22:17:18 [boto] ERROR: Caught exception reading instance data
Traceback (most recent call last):
  File "E:\Anaconda\lib\site-packages\boto\utils.py", line 210, in retry_url
    r = opener.open(req, timeout=timeout)
  File "E:\Anaconda\lib\urllib2.py", line 431, in open
    response = self._open(req, data)
  File "E:\Anaconda\lib\urllib2.py", line 449, in _open
    '_open', req)
  File "E:\Anaconda\lib\urllib2.py", line 409, in _call_chain
    result = func(*args)
  File "E:\Anaconda\lib\urllib2.py", line 1227, in http_open
    return self.do_open(httplib.HTTPConnection, req)
  File "E:\Anaconda\lib\urllib2.py", line 1197, in do_open
    raise URLError(err)
URLError: <urlopen error [Errno 10051] >
2015-07-23 22:17:18 [boto] ERROR: Unable to read instance data, giving up
2015-07-23 22:25:24 [boto] ERROR: Caught exception reading instance data
Traceback (most recent call last):
  File "E:\Anaconda\lib\site-packages\boto\utils.py", line 210, in retry_url
    r = opener.open(req, timeout=timeout)
  File "E:\Anaconda\lib\urllib2.py", line 431, in open
    response = self._open(req, data)
  File "E:\Anaconda\lib\urllib2.py", line 449, in _open
    '_open', req)
  File "E:\Anaconda\lib\urllib2.py", line 409, in _call_chain
    result = func(*args)
  File "E:\Anaconda\lib\urllib2.py", line 1227, in http_open
    return self.do_open(httplib.HTTPConnection, req)
  File "E:\Anaconda\lib\urllib2.py", line 1197, in do_open
    raise URLError(err)
URLError: <urlopen error [Errno 10051] >
2015-07-23 22:25:24 [boto] ERROR: Unable to read instance data, giving up
2015-07-23 22:44:48 [scrapy] ERROR: Spider error processing <GET http://guba.sina.com.cn/?s=thread&tid=10295&bid=567> (referer: http://guba.sina.com.cn/?s=thread&tid=10295&bid=567)
Traceback (most recent call last):
  File "E:\Anaconda\lib\site-packages\scrapy\utils\defer.py", line 102, in iter_errback
    yield next(it)
  File "E:\Anaconda\lib\site-packages\scrapy\spidermiddlewares\offsite.py", line 28, in process_spider_output
    for x in result:
  File "E:\Anaconda\lib\site-packages\scrapy\spidermiddlewares\referer.py", line 22, in <genexpr>
    return (_set_referer(r) for r in result or ())
  File "E:\Anaconda\lib\site-packages\scrapy\spidermiddlewares\urllength.py", line 37, in <genexpr>
    return (r for r in result or () if _filter(r))
  File "E:\Anaconda\lib\site-packages\scrapy\spidermiddlewares\depth.py", line 54, in <genexpr>
    return (r for r in result or () if _filter(r))
  File "E:\liyi\stockAnaly\crawl\sinabbsCrawler\sinabbsCrawler\spiders\sinabbsSpider.py", line 276, in parseComment
    Date,Time = self.extracttime(text)
  File "E:\liyi\stockAnaly\crawl\sinabbsCrawler\sinabbsCrawler\spiders\sinabbsSpider.py", line 115, in extracttime
    return date(int(year),int(month),int(day)),time(0,0,0)
ValueError: day is out of range for month
2015-07-23 22:45:19 [scrapy] ERROR: Spider error processing <GET http://guba.sina.com.cn/?s=thread&tid=10306&bid=567> (referer: http://guba.sina.com.cn/?s=thread&tid=10306&bid=567)
Traceback (most recent call last):
  File "E:\Anaconda\lib\site-packages\scrapy\utils\defer.py", line 102, in iter_errback
    yield next(it)
  File "E:\Anaconda\lib\site-packages\scrapy\spidermiddlewares\offsite.py", line 28, in process_spider_output
    for x in result:
  File "E:\Anaconda\lib\site-packages\scrapy\spidermiddlewares\referer.py", line 22, in <genexpr>
    return (_set_referer(r) for r in result or ())
  File "E:\Anaconda\lib\site-packages\scrapy\spidermiddlewares\urllength.py", line 37, in <genexpr>
    return (r for r in result or () if _filter(r))
  File "E:\Anaconda\lib\site-packages\scrapy\spidermiddlewares\depth.py", line 54, in <genexpr>
    return (r for r in result or () if _filter(r))
  File "E:\liyi\stockAnaly\crawl\sinabbsCrawler\sinabbsCrawler\spiders\sinabbsSpider.py", line 276, in parseComment
    Date,Time = self.extracttime(text)
  File "E:\liyi\stockAnaly\crawl\sinabbsCrawler\sinabbsCrawler\spiders\sinabbsSpider.py", line 115, in extracttime
    return date(int(year),int(month),int(day)),time(0,0,0)
ValueError: day is out of range for month
2015-07-23 22:45:20 [scrapy] ERROR: Spider error processing <GET http://guba.sina.com.cn/?s=thread&tid=10294&bid=567> (referer: http://guba.sina.com.cn/?s=thread&tid=10294&bid=567)
Traceback (most recent call last):
  File "E:\Anaconda\lib\site-packages\scrapy\utils\defer.py", line 102, in iter_errback
    yield next(it)
  File "E:\Anaconda\lib\site-packages\scrapy\spidermiddlewares\offsite.py", line 28, in process_spider_output
    for x in result:
  File "E:\Anaconda\lib\site-packages\scrapy\spidermiddlewares\referer.py", line 22, in <genexpr>
    return (_set_referer(r) for r in result or ())
  File "E:\Anaconda\lib\site-packages\scrapy\spidermiddlewares\urllength.py", line 37, in <genexpr>
    return (r for r in result or () if _filter(r))
  File "E:\Anaconda\lib\site-packages\scrapy\spidermiddlewares\depth.py", line 54, in <genexpr>
    return (r for r in result or () if _filter(r))
  File "E:\liyi\stockAnaly\crawl\sinabbsCrawler\sinabbsCrawler\spiders\sinabbsSpider.py", line 276, in parseComment
    Date,Time = self.extracttime(text)
  File "E:\liyi\stockAnaly\crawl\sinabbsCrawler\sinabbsCrawler\spiders\sinabbsSpider.py", line 115, in extracttime
    return date(int(year),int(month),int(day)),time(0,0,0)
ValueError: day is out of range for month
2015-07-23 22:45:20 [scrapy] ERROR: Spider error processing <GET http://guba.sina.com.cn/?s=thread&tid=9755&bid=567> (referer: http://guba.sina.com.cn/?s=thread&tid=9755&bid=567)
Traceback (most recent call last):
  File "E:\Anaconda\lib\site-packages\scrapy\utils\defer.py", line 102, in iter_errback
    yield next(it)
  File "E:\Anaconda\lib\site-packages\scrapy\spidermiddlewares\offsite.py", line 28, in process_spider_output
    for x in result:
  File "E:\Anaconda\lib\site-packages\scrapy\spidermiddlewares\referer.py", line 22, in <genexpr>
    return (_set_referer(r) for r in result or ())
  File "E:\Anaconda\lib\site-packages\scrapy\spidermiddlewares\urllength.py", line 37, in <genexpr>
    return (r for r in result or () if _filter(r))
  File "E:\Anaconda\lib\site-packages\scrapy\spidermiddlewares\depth.py", line 54, in <genexpr>
    return (r for r in result or () if _filter(r))
  File "E:\liyi\stockAnaly\crawl\sinabbsCrawler\sinabbsCrawler\spiders\sinabbsSpider.py", line 276, in parseComment
    Date,Time = self.extracttime(text)
  File "E:\liyi\stockAnaly\crawl\sinabbsCrawler\sinabbsCrawler\spiders\sinabbsSpider.py", line 115, in extracttime
    return date(int(year),int(month),int(day)),time(0,0,0)
ValueError: day is out of range for month
2015-07-23 23:00:00 [boto] ERROR: Caught exception reading instance data
Traceback (most recent call last):
  File "E:\Anaconda\lib\site-packages\boto\utils.py", line 210, in retry_url
    r = opener.open(req, timeout=timeout)
  File "E:\Anaconda\lib\urllib2.py", line 431, in open
    response = self._open(req, data)
  File "E:\Anaconda\lib\urllib2.py", line 449, in _open
    '_open', req)
  File "E:\Anaconda\lib\urllib2.py", line 409, in _call_chain
    result = func(*args)
  File "E:\Anaconda\lib\urllib2.py", line 1227, in http_open
    return self.do_open(httplib.HTTPConnection, req)
  File "E:\Anaconda\lib\urllib2.py", line 1197, in do_open
    raise URLError(err)
URLError: <urlopen error [Errno 10051] >
2015-07-23 23:00:00 [boto] ERROR: Unable to read instance data, giving up
2015-07-23 23:11:35 [scrapy] ERROR: Spider error processing <GET http://guba.sina.com.cn/?s=thread&tid=13637&bid=1643> (referer: http://guba.sina.com.cn/?s=thread&tid=13637&bid=1643)
Traceback (most recent call last):
  File "E:\Anaconda\lib\site-packages\scrapy\utils\defer.py", line 102, in iter_errback
    yield next(it)
  File "E:\Anaconda\lib\site-packages\scrapy\spidermiddlewares\offsite.py", line 28, in process_spider_output
    for x in result:
  File "E:\Anaconda\lib\site-packages\scrapy\spidermiddlewares\referer.py", line 22, in <genexpr>
    return (_set_referer(r) for r in result or ())
  File "E:\Anaconda\lib\site-packages\scrapy\spidermiddlewares\urllength.py", line 37, in <genexpr>
    return (r for r in result or () if _filter(r))
  File "E:\Anaconda\lib\site-packages\scrapy\spidermiddlewares\depth.py", line 54, in <genexpr>
    return (r for r in result or () if _filter(r))
  File "E:\liyi\stockAnaly\crawl\sinabbsCrawler\sinabbsCrawler\spiders\sinabbsSpider.py", line 276, in parseComment
    Date,Time = self.extracttime(text)
  File "E:\liyi\stockAnaly\crawl\sinabbsCrawler\sinabbsCrawler\spiders\sinabbsSpider.py", line 115, in extracttime
    return date(int(year),int(month),int(day)),time(0,0,0)
ValueError: day is out of range for month
2015-07-23 23:11:49 [scrapy] ERROR: Spider error processing <GET http://guba.sina.com.cn/?s=thread&tid=13641&bid=1643> (referer: http://guba.sina.com.cn/?s=thread&tid=13641&bid=1643)
Traceback (most recent call last):
  File "E:\Anaconda\lib\site-packages\scrapy\utils\defer.py", line 102, in iter_errback
    yield next(it)
  File "E:\Anaconda\lib\site-packages\scrapy\spidermiddlewares\offsite.py", line 28, in process_spider_output
    for x in result:
  File "E:\Anaconda\lib\site-packages\scrapy\spidermiddlewares\referer.py", line 22, in <genexpr>
    return (_set_referer(r) for r in result or ())
  File "E:\Anaconda\lib\site-packages\scrapy\spidermiddlewares\urllength.py", line 37, in <genexpr>
    return (r for r in result or () if _filter(r))
  File "E:\Anaconda\lib\site-packages\scrapy\spidermiddlewares\depth.py", line 54, in <genexpr>
    return (r for r in result or () if _filter(r))
  File "E:\liyi\stockAnaly\crawl\sinabbsCrawler\sinabbsCrawler\spiders\sinabbsSpider.py", line 276, in parseComment
    Date,Time = self.extracttime(text)
  File "E:\liyi\stockAnaly\crawl\sinabbsCrawler\sinabbsCrawler\spiders\sinabbsSpider.py", line 115, in extracttime
    return date(int(year),int(month),int(day)),time(0,0,0)
ValueError: day is out of range for month
2015-07-23 23:19:18 [boto] ERROR: Caught exception reading instance data
Traceback (most recent call last):
  File "E:\Anaconda\lib\site-packages\boto\utils.py", line 210, in retry_url
    r = opener.open(req, timeout=timeout)
  File "E:\Anaconda\lib\urllib2.py", line 431, in open
    response = self._open(req, data)
  File "E:\Anaconda\lib\urllib2.py", line 449, in _open
    '_open', req)
  File "E:\Anaconda\lib\urllib2.py", line 409, in _call_chain
    result = func(*args)
  File "E:\Anaconda\lib\urllib2.py", line 1227, in http_open
    return self.do_open(httplib.HTTPConnection, req)
  File "E:\Anaconda\lib\urllib2.py", line 1197, in do_open
    raise URLError(err)
URLError: <urlopen error [Errno 10051] >
2015-07-23 23:19:18 [boto] ERROR: Unable to read instance data, giving up
2015-07-23 23:32:01 [boto] ERROR: Caught exception reading instance data
Traceback (most recent call last):
  File "E:\Anaconda\lib\site-packages\boto\utils.py", line 210, in retry_url
    r = opener.open(req, timeout=timeout)
  File "E:\Anaconda\lib\urllib2.py", line 431, in open
    response = self._open(req, data)
  File "E:\Anaconda\lib\urllib2.py", line 449, in _open
    '_open', req)
  File "E:\Anaconda\lib\urllib2.py", line 409, in _call_chain
    result = func(*args)
  File "E:\Anaconda\lib\urllib2.py", line 1227, in http_open
    return self.do_open(httplib.HTTPConnection, req)
  File "E:\Anaconda\lib\urllib2.py", line 1197, in do_open
    raise URLError(err)
URLError: <urlopen error [Errno 10051] >
2015-07-23 23:32:01 [boto] ERROR: Unable to read instance data, giving up
2015-07-23 23:36:05 [boto] ERROR: Caught exception reading instance data
Traceback (most recent call last):
  File "E:\Anaconda\lib\site-packages\boto\utils.py", line 210, in retry_url
    r = opener.open(req, timeout=timeout)
  File "E:\Anaconda\lib\urllib2.py", line 431, in open
    response = self._open(req, data)
  File "E:\Anaconda\lib\urllib2.py", line 449, in _open
    '_open', req)
  File "E:\Anaconda\lib\urllib2.py", line 409, in _call_chain
    result = func(*args)
  File "E:\Anaconda\lib\urllib2.py", line 1227, in http_open
    return self.do_open(httplib.HTTPConnection, req)
  File "E:\Anaconda\lib\urllib2.py", line 1197, in do_open
    raise URLError(err)
URLError: <urlopen error [Errno 10051] >
2015-07-23 23:36:05 [boto] ERROR: Unable to read instance data, giving up
2015-07-23 23:52:31 [scrapy] ERROR: Spider error processing <GET http://guba.sina.com.cn/?s=thread&tid=12686&bid=1164&page=4> (referer: http://guba.sina.com.cn/?s=thread&tid=12686&bid=1164&page=3)
Traceback (most recent call last):
  File "E:\Anaconda\lib\site-packages\scrapy\utils\defer.py", line 102, in iter_errback
    yield next(it)
  File "E:\Anaconda\lib\site-packages\scrapy\spidermiddlewares\offsite.py", line 28, in process_spider_output
    for x in result:
  File "E:\Anaconda\lib\site-packages\scrapy\spidermiddlewares\referer.py", line 22, in <genexpr>
    return (_set_referer(r) for r in result or ())
  File "E:\Anaconda\lib\site-packages\scrapy\spidermiddlewares\urllength.py", line 37, in <genexpr>
    return (r for r in result or () if _filter(r))
  File "E:\Anaconda\lib\site-packages\scrapy\spidermiddlewares\depth.py", line 54, in <genexpr>
    return (r for r in result or () if _filter(r))
  File "E:\liyi\stockAnaly\crawl\sinabbsCrawler\sinabbsCrawler\spiders\sinabbsSpider.py", line 276, in parseComment
    Date,Time = self.extracttime(text)
  File "E:\liyi\stockAnaly\crawl\sinabbsCrawler\sinabbsCrawler\spiders\sinabbsSpider.py", line 115, in extracttime
    return date(int(year),int(month),int(day)),time(0,0,0)
ValueError: day is out of range for month
2015-07-23 23:58:02 [scrapy] ERROR: Spider error processing <GET http://guba.sina.com.cn/?s=thread&tid=12923&bid=1164> (referer: http://guba.sina.com.cn/?s=thread&tid=12923&bid=1164)
Traceback (most recent call last):
  File "E:\Anaconda\lib\site-packages\scrapy\utils\defer.py", line 102, in iter_errback
    yield next(it)
  File "E:\Anaconda\lib\site-packages\scrapy\spidermiddlewares\offsite.py", line 28, in process_spider_output
    for x in result:
  File "E:\Anaconda\lib\site-packages\scrapy\spidermiddlewares\referer.py", line 22, in <genexpr>
    return (_set_referer(r) for r in result or ())
  File "E:\Anaconda\lib\site-packages\scrapy\spidermiddlewares\urllength.py", line 37, in <genexpr>
    return (r for r in result or () if _filter(r))
  File "E:\Anaconda\lib\site-packages\scrapy\spidermiddlewares\depth.py", line 54, in <genexpr>
    return (r for r in result or () if _filter(r))
  File "E:\liyi\stockAnaly\crawl\sinabbsCrawler\sinabbsCrawler\spiders\sinabbsSpider.py", line 276, in parseComment
    Date,Time = self.extracttime(text)
  File "E:\liyi\stockAnaly\crawl\sinabbsCrawler\sinabbsCrawler\spiders\sinabbsSpider.py", line 115, in extracttime
    return date(int(year),int(month),int(day)),time(0,0,0)
ValueError: day is out of range for month
2015-07-23 23:58:18 [scrapy] ERROR: Spider error processing <GET http://guba.sina.com.cn/?s=thread&tid=12870&bid=1164> (referer: http://guba.sina.com.cn/?s=thread&tid=12870&bid=1164)
Traceback (most recent call last):
  File "E:\Anaconda\lib\site-packages\scrapy\utils\defer.py", line 102, in iter_errback
    yield next(it)
  File "E:\Anaconda\lib\site-packages\scrapy\spidermiddlewares\offsite.py", line 28, in process_spider_output
    for x in result:
  File "E:\Anaconda\lib\site-packages\scrapy\spidermiddlewares\referer.py", line 22, in <genexpr>
    return (_set_referer(r) for r in result or ())
  File "E:\Anaconda\lib\site-packages\scrapy\spidermiddlewares\urllength.py", line 37, in <genexpr>
    return (r for r in result or () if _filter(r))
  File "E:\Anaconda\lib\site-packages\scrapy\spidermiddlewares\depth.py", line 54, in <genexpr>
    return (r for r in result or () if _filter(r))
  File "E:\liyi\stockAnaly\crawl\sinabbsCrawler\sinabbsCrawler\spiders\sinabbsSpider.py", line 276, in parseComment
    Date,Time = self.extracttime(text)
  File "E:\liyi\stockAnaly\crawl\sinabbsCrawler\sinabbsCrawler\spiders\sinabbsSpider.py", line 115, in extracttime
    return date(int(year),int(month),int(day)),time(0,0,0)
ValueError: day is out of range for month
2015-07-23 23:58:19 [scrapy] ERROR: Spider error processing <GET http://guba.sina.com.cn/?s=thread&tid=12905&bid=1164> (referer: http://guba.sina.com.cn/?s=thread&tid=12905&bid=1164)
Traceback (most recent call last):
  File "E:\Anaconda\lib\site-packages\scrapy\utils\defer.py", line 102, in iter_errback
    yield next(it)
  File "E:\Anaconda\lib\site-packages\scrapy\spidermiddlewares\offsite.py", line 28, in process_spider_output
    for x in result:
  File "E:\Anaconda\lib\site-packages\scrapy\spidermiddlewares\referer.py", line 22, in <genexpr>
    return (_set_referer(r) for r in result or ())
  File "E:\Anaconda\lib\site-packages\scrapy\spidermiddlewares\urllength.py", line 37, in <genexpr>
    return (r for r in result or () if _filter(r))
  File "E:\Anaconda\lib\site-packages\scrapy\spidermiddlewares\depth.py", line 54, in <genexpr>
    return (r for r in result or () if _filter(r))
  File "E:\liyi\stockAnaly\crawl\sinabbsCrawler\sinabbsCrawler\spiders\sinabbsSpider.py", line 276, in parseComment
    Date,Time = self.extracttime(text)
  File "E:\liyi\stockAnaly\crawl\sinabbsCrawler\sinabbsCrawler\spiders\sinabbsSpider.py", line 115, in extracttime
    return date(int(year),int(month),int(day)),time(0,0,0)
ValueError: day is out of range for month
2015-07-24 00:02:41 [scrapy] ERROR: Spider error processing <GET http://guba.sina.com.cn/?s=thread&tid=12626&bid=1164&page=3> (referer: http://guba.sina.com.cn/?s=thread&tid=12626&bid=1164&page=2)
Traceback (most recent call last):
  File "E:\Anaconda\lib\site-packages\scrapy\utils\defer.py", line 102, in iter_errback
    yield next(it)
  File "E:\Anaconda\lib\site-packages\scrapy\spidermiddlewares\offsite.py", line 28, in process_spider_output
    for x in result:
  File "E:\Anaconda\lib\site-packages\scrapy\spidermiddlewares\referer.py", line 22, in <genexpr>
    return (_set_referer(r) for r in result or ())
  File "E:\Anaconda\lib\site-packages\scrapy\spidermiddlewares\urllength.py", line 37, in <genexpr>
    return (r for r in result or () if _filter(r))
  File "E:\Anaconda\lib\site-packages\scrapy\spidermiddlewares\depth.py", line 54, in <genexpr>
    return (r for r in result or () if _filter(r))
  File "E:\liyi\stockAnaly\crawl\sinabbsCrawler\sinabbsCrawler\spiders\sinabbsSpider.py", line 276, in parseComment
    Date,Time = self.extracttime(text)
  File "E:\liyi\stockAnaly\crawl\sinabbsCrawler\sinabbsCrawler\spiders\sinabbsSpider.py", line 115, in extracttime
    return date(int(year),int(month),int(day)),time(0,0,0)
ValueError: day is out of range for month
2015-07-24 00:07:41 [boto] ERROR: Caught exception reading instance data
Traceback (most recent call last):
  File "E:\Anaconda\lib\site-packages\boto\utils.py", line 210, in retry_url
    r = opener.open(req, timeout=timeout)
  File "E:\Anaconda\lib\urllib2.py", line 431, in open
    response = self._open(req, data)
  File "E:\Anaconda\lib\urllib2.py", line 449, in _open
    '_open', req)
  File "E:\Anaconda\lib\urllib2.py", line 409, in _call_chain
    result = func(*args)
  File "E:\Anaconda\lib\urllib2.py", line 1227, in http_open
    return self.do_open(httplib.HTTPConnection, req)
  File "E:\Anaconda\lib\urllib2.py", line 1197, in do_open
    raise URLError(err)
URLError: <urlopen error [Errno 10051] >
2015-07-24 00:07:41 [boto] ERROR: Unable to read instance data, giving up
2015-07-24 00:35:25 [scrapy] ERROR: Spider error processing <GET http://guba.sina.com.cn/?s=thread&tid=10018&bid=1557> (referer: http://guba.sina.com.cn/?s=thread&tid=10018&bid=1557)
Traceback (most recent call last):
  File "E:\Anaconda\lib\site-packages\scrapy\utils\defer.py", line 102, in iter_errback
    yield next(it)
  File "E:\Anaconda\lib\site-packages\scrapy\spidermiddlewares\offsite.py", line 28, in process_spider_output
    for x in result:
  File "E:\Anaconda\lib\site-packages\scrapy\spidermiddlewares\referer.py", line 22, in <genexpr>
    return (_set_referer(r) for r in result or ())
  File "E:\Anaconda\lib\site-packages\scrapy\spidermiddlewares\urllength.py", line 37, in <genexpr>
    return (r for r in result or () if _filter(r))
  File "E:\Anaconda\lib\site-packages\scrapy\spidermiddlewares\depth.py", line 54, in <genexpr>
    return (r for r in result or () if _filter(r))
  File "E:\liyi\stockAnaly\crawl\sinabbsCrawler\sinabbsCrawler\spiders\sinabbsSpider.py", line 276, in parseComment
    Date,Time = self.extracttime(text)
  File "E:\liyi\stockAnaly\crawl\sinabbsCrawler\sinabbsCrawler\spiders\sinabbsSpider.py", line 115, in extracttime
    return date(int(year),int(month),int(day)),time(0,0,0)
ValueError: day is out of range for month
2015-07-24 00:37:19 [scrapy] ERROR: Spider error processing <GET http://guba.sina.com.cn/?s=thread&tid=7169&bid=1557&page=2> (referer: http://guba.sina.com.cn/?s=thread&tid=7169&bid=1557)
Traceback (most recent call last):
  File "E:\Anaconda\lib\site-packages\scrapy\utils\defer.py", line 102, in iter_errback
    yield next(it)
  File "E:\Anaconda\lib\site-packages\scrapy\spidermiddlewares\offsite.py", line 28, in process_spider_output
    for x in result:
  File "E:\Anaconda\lib\site-packages\scrapy\spidermiddlewares\referer.py", line 22, in <genexpr>
    return (_set_referer(r) for r in result or ())
  File "E:\Anaconda\lib\site-packages\scrapy\spidermiddlewares\urllength.py", line 37, in <genexpr>
    return (r for r in result or () if _filter(r))
  File "E:\Anaconda\lib\site-packages\scrapy\spidermiddlewares\depth.py", line 54, in <genexpr>
    return (r for r in result or () if _filter(r))
  File "E:\liyi\stockAnaly\crawl\sinabbsCrawler\sinabbsCrawler\spiders\sinabbsSpider.py", line 276, in parseComment
    Date,Time = self.extracttime(text)
  File "E:\liyi\stockAnaly\crawl\sinabbsCrawler\sinabbsCrawler\spiders\sinabbsSpider.py", line 115, in extracttime
    return date(int(year),int(month),int(day)),time(0,0,0)
ValueError: day is out of range for month
2015-07-24 00:38:54 [boto] ERROR: Caught exception reading instance data
Traceback (most recent call last):
  File "E:\Anaconda\lib\site-packages\boto\utils.py", line 210, in retry_url
    r = opener.open(req, timeout=timeout)
  File "E:\Anaconda\lib\urllib2.py", line 431, in open
    response = self._open(req, data)
  File "E:\Anaconda\lib\urllib2.py", line 449, in _open
    '_open', req)
  File "E:\Anaconda\lib\urllib2.py", line 409, in _call_chain
    result = func(*args)
  File "E:\Anaconda\lib\urllib2.py", line 1227, in http_open
    return self.do_open(httplib.HTTPConnection, req)
  File "E:\Anaconda\lib\urllib2.py", line 1197, in do_open
    raise URLError(err)
URLError: <urlopen error [Errno 10051] >
2015-07-24 00:38:54 [boto] ERROR: Unable to read instance data, giving up
2015-07-24 00:41:55 [boto] ERROR: Caught exception reading instance data
Traceback (most recent call last):
  File "E:\Anaconda\lib\site-packages\boto\utils.py", line 210, in retry_url
    r = opener.open(req, timeout=timeout)
  File "E:\Anaconda\lib\urllib2.py", line 431, in open
    response = self._open(req, data)
  File "E:\Anaconda\lib\urllib2.py", line 449, in _open
    '_open', req)
  File "E:\Anaconda\lib\urllib2.py", line 409, in _call_chain
    result = func(*args)
  File "E:\Anaconda\lib\urllib2.py", line 1227, in http_open
    return self.do_open(httplib.HTTPConnection, req)
  File "E:\Anaconda\lib\urllib2.py", line 1197, in do_open
    raise URLError(err)
URLError: <urlopen error [Errno 10051] >
2015-07-24 00:41:55 [boto] ERROR: Unable to read instance data, giving up
2015-07-24 00:46:59 [scrapy] ERROR: Spider error processing <GET http://guba.sina.com.cn/?s=thread&tid=17220&bid=614> (referer: http://guba.sina.com.cn/?s=thread&tid=17220&bid=614)
Traceback (most recent call last):
  File "E:\Anaconda\lib\site-packages\scrapy\utils\defer.py", line 102, in iter_errback
    yield next(it)
  File "E:\Anaconda\lib\site-packages\scrapy\spidermiddlewares\offsite.py", line 28, in process_spider_output
    for x in result:
  File "E:\Anaconda\lib\site-packages\scrapy\spidermiddlewares\referer.py", line 22, in <genexpr>
    return (_set_referer(r) for r in result or ())
  File "E:\Anaconda\lib\site-packages\scrapy\spidermiddlewares\urllength.py", line 37, in <genexpr>
    return (r for r in result or () if _filter(r))
  File "E:\Anaconda\lib\site-packages\scrapy\spidermiddlewares\depth.py", line 54, in <genexpr>
    return (r for r in result or () if _filter(r))
  File "E:\liyi\stockAnaly\crawl\sinabbsCrawler\sinabbsCrawler\spiders\sinabbsSpider.py", line 276, in parseComment
    Date,Time = self.extracttime(text)
  File "E:\liyi\stockAnaly\crawl\sinabbsCrawler\sinabbsCrawler\spiders\sinabbsSpider.py", line 115, in extracttime
    return date(int(year),int(month),int(day)),time(0,0,0)
ValueError: day is out of range for month
2015-07-24 00:49:16 [scrapy] ERROR: Spider error processing <GET http://guba.sina.com.cn/?s=thread&tid=17291&bid=614> (referer: http://guba.sina.com.cn/?s=thread&tid=17291&bid=614)
Traceback (most recent call last):
  File "E:\Anaconda\lib\site-packages\scrapy\utils\defer.py", line 102, in iter_errback
    yield next(it)
  File "E:\Anaconda\lib\site-packages\scrapy\spidermiddlewares\offsite.py", line 28, in process_spider_output
    for x in result:
  File "E:\Anaconda\lib\site-packages\scrapy\spidermiddlewares\referer.py", line 22, in <genexpr>
    return (_set_referer(r) for r in result or ())
  File "E:\Anaconda\lib\site-packages\scrapy\spidermiddlewares\urllength.py", line 37, in <genexpr>
    return (r for r in result or () if _filter(r))
  File "E:\Anaconda\lib\site-packages\scrapy\spidermiddlewares\depth.py", line 54, in <genexpr>
    return (r for r in result or () if _filter(r))
  File "E:\liyi\stockAnaly\crawl\sinabbsCrawler\sinabbsCrawler\spiders\sinabbsSpider.py", line 276, in parseComment
    Date,Time = self.extracttime(text)
  File "E:\liyi\stockAnaly\crawl\sinabbsCrawler\sinabbsCrawler\spiders\sinabbsSpider.py", line 115, in extracttime
    return date(int(year),int(month),int(day)),time(0,0,0)
ValueError: day is out of range for month
2015-07-24 00:58:48 [scrapy] ERROR: Spider error processing <GET http://guba.sina.com.cn/?s=thread&tid=12028&bid=614&page=3> (referer: http://guba.sina.com.cn/?s=thread&tid=12028&bid=614&page=2)
Traceback (most recent call last):
  File "E:\Anaconda\lib\site-packages\scrapy\utils\defer.py", line 102, in iter_errback
    yield next(it)
  File "E:\Anaconda\lib\site-packages\scrapy\spidermiddlewares\offsite.py", line 28, in process_spider_output
    for x in result:
  File "E:\Anaconda\lib\site-packages\scrapy\spidermiddlewares\referer.py", line 22, in <genexpr>
    return (_set_referer(r) for r in result or ())
  File "E:\Anaconda\lib\site-packages\scrapy\spidermiddlewares\urllength.py", line 37, in <genexpr>
    return (r for r in result or () if _filter(r))
  File "E:\Anaconda\lib\site-packages\scrapy\spidermiddlewares\depth.py", line 54, in <genexpr>
    return (r for r in result or () if _filter(r))
  File "E:\liyi\stockAnaly\crawl\sinabbsCrawler\sinabbsCrawler\spiders\sinabbsSpider.py", line 276, in parseComment
    Date,Time = self.extracttime(text)
  File "E:\liyi\stockAnaly\crawl\sinabbsCrawler\sinabbsCrawler\spiders\sinabbsSpider.py", line 115, in extracttime
    return date(int(year),int(month),int(day)),time(0,0,0)
ValueError: day is out of range for month
2015-07-24 01:01:51 [boto] ERROR: Caught exception reading instance data
Traceback (most recent call last):
  File "E:\Anaconda\lib\site-packages\boto\utils.py", line 210, in retry_url
    r = opener.open(req, timeout=timeout)
  File "E:\Anaconda\lib\urllib2.py", line 431, in open
    response = self._open(req, data)
  File "E:\Anaconda\lib\urllib2.py", line 449, in _open
    '_open', req)
  File "E:\Anaconda\lib\urllib2.py", line 409, in _call_chain
    result = func(*args)
  File "E:\Anaconda\lib\urllib2.py", line 1227, in http_open
    return self.do_open(httplib.HTTPConnection, req)
  File "E:\Anaconda\lib\urllib2.py", line 1197, in do_open
    raise URLError(err)
URLError: <urlopen error [Errno 10051] >
2015-07-24 01:01:51 [boto] ERROR: Unable to read instance data, giving up
2015-07-24 01:04:12 [boto] ERROR: Caught exception reading instance data
Traceback (most recent call last):
  File "E:\Anaconda\lib\site-packages\boto\utils.py", line 210, in retry_url
    r = opener.open(req, timeout=timeout)
  File "E:\Anaconda\lib\urllib2.py", line 431, in open
    response = self._open(req, data)
  File "E:\Anaconda\lib\urllib2.py", line 449, in _open
    '_open', req)
  File "E:\Anaconda\lib\urllib2.py", line 409, in _call_chain
    result = func(*args)
  File "E:\Anaconda\lib\urllib2.py", line 1227, in http_open
    return self.do_open(httplib.HTTPConnection, req)
  File "E:\Anaconda\lib\urllib2.py", line 1197, in do_open
    raise URLError(err)
URLError: <urlopen error [Errno 10051] >
2015-07-24 01:04:12 [boto] ERROR: Unable to read instance data, giving up
2015-07-24 01:08:04 [boto] ERROR: Caught exception reading instance data
Traceback (most recent call last):
  File "E:\Anaconda\lib\site-packages\boto\utils.py", line 210, in retry_url
    r = opener.open(req, timeout=timeout)
  File "E:\Anaconda\lib\urllib2.py", line 431, in open
    response = self._open(req, data)
  File "E:\Anaconda\lib\urllib2.py", line 449, in _open
    '_open', req)
  File "E:\Anaconda\lib\urllib2.py", line 409, in _call_chain
    result = func(*args)
  File "E:\Anaconda\lib\urllib2.py", line 1227, in http_open
    return self.do_open(httplib.HTTPConnection, req)
  File "E:\Anaconda\lib\urllib2.py", line 1197, in do_open
    raise URLError(err)
URLError: <urlopen error [Errno 10051] >
2015-07-24 01:08:04 [boto] ERROR: Unable to read instance data, giving up
2015-07-24 01:21:48 [scrapy] ERROR: Spider error processing <GET http://guba.sina.com.cn/?s=thread&tid=12882&bid=169> (referer: http://guba.sina.com.cn/?s=thread&tid=12882&bid=169)
Traceback (most recent call last):
  File "E:\Anaconda\lib\site-packages\scrapy\utils\defer.py", line 102, in iter_errback
    yield next(it)
  File "E:\Anaconda\lib\site-packages\scrapy\spidermiddlewares\offsite.py", line 28, in process_spider_output
    for x in result:
  File "E:\Anaconda\lib\site-packages\scrapy\spidermiddlewares\referer.py", line 22, in <genexpr>
    return (_set_referer(r) for r in result or ())
  File "E:\Anaconda\lib\site-packages\scrapy\spidermiddlewares\urllength.py", line 37, in <genexpr>
    return (r for r in result or () if _filter(r))
  File "E:\Anaconda\lib\site-packages\scrapy\spidermiddlewares\depth.py", line 54, in <genexpr>
    return (r for r in result or () if _filter(r))
  File "E:\liyi\stockAnaly\crawl\sinabbsCrawler\sinabbsCrawler\spiders\sinabbsSpider.py", line 276, in parseComment
    Date,Time = self.extracttime(text)
  File "E:\liyi\stockAnaly\crawl\sinabbsCrawler\sinabbsCrawler\spiders\sinabbsSpider.py", line 115, in extracttime
    return date(int(year),int(month),int(day)),time(0,0,0)
ValueError: day is out of range for month
2015-07-24 01:21:48 [scrapy] ERROR: Spider error processing <GET http://guba.sina.com.cn/?s=thread&tid=11025&bid=169> (referer: http://guba.sina.com.cn/?s=thread&tid=11025&bid=169)
Traceback (most recent call last):
  File "E:\Anaconda\lib\site-packages\scrapy\utils\defer.py", line 102, in iter_errback
    yield next(it)
  File "E:\Anaconda\lib\site-packages\scrapy\spidermiddlewares\offsite.py", line 28, in process_spider_output
    for x in result:
  File "E:\Anaconda\lib\site-packages\scrapy\spidermiddlewares\referer.py", line 22, in <genexpr>
    return (_set_referer(r) for r in result or ())
  File "E:\Anaconda\lib\site-packages\scrapy\spidermiddlewares\urllength.py", line 37, in <genexpr>
    return (r for r in result or () if _filter(r))
  File "E:\Anaconda\lib\site-packages\scrapy\spidermiddlewares\depth.py", line 54, in <genexpr>
    return (r for r in result or () if _filter(r))
  File "E:\liyi\stockAnaly\crawl\sinabbsCrawler\sinabbsCrawler\spiders\sinabbsSpider.py", line 276, in parseComment
    Date,Time = self.extracttime(text)
  File "E:\liyi\stockAnaly\crawl\sinabbsCrawler\sinabbsCrawler\spiders\sinabbsSpider.py", line 115, in extracttime
    return date(int(year),int(month),int(day)),time(0,0,0)
ValueError: day is out of range for month
2015-07-24 01:21:53 [scrapy] ERROR: Spider error processing <GET http://guba.sina.com.cn/?s=thread&tid=12568&bid=169> (referer: http://guba.sina.com.cn/?s=thread&tid=12568&bid=169)
Traceback (most recent call last):
  File "E:\Anaconda\lib\site-packages\scrapy\utils\defer.py", line 102, in iter_errback
    yield next(it)
  File "E:\Anaconda\lib\site-packages\scrapy\spidermiddlewares\offsite.py", line 28, in process_spider_output
    for x in result:
  File "E:\Anaconda\lib\site-packages\scrapy\spidermiddlewares\referer.py", line 22, in <genexpr>
    return (_set_referer(r) for r in result or ())
  File "E:\Anaconda\lib\site-packages\scrapy\spidermiddlewares\urllength.py", line 37, in <genexpr>
    return (r for r in result or () if _filter(r))
  File "E:\Anaconda\lib\site-packages\scrapy\spidermiddlewares\depth.py", line 54, in <genexpr>
    return (r for r in result or () if _filter(r))
  File "E:\liyi\stockAnaly\crawl\sinabbsCrawler\sinabbsCrawler\spiders\sinabbsSpider.py", line 276, in parseComment
    Date,Time = self.extracttime(text)
  File "E:\liyi\stockAnaly\crawl\sinabbsCrawler\sinabbsCrawler\spiders\sinabbsSpider.py", line 115, in extracttime
    return date(int(year),int(month),int(day)),time(0,0,0)
ValueError: day is out of range for month
2015-07-24 01:39:48 [boto] ERROR: Caught exception reading instance data
Traceback (most recent call last):
  File "E:\Anaconda\lib\site-packages\boto\utils.py", line 210, in retry_url
    r = opener.open(req, timeout=timeout)
  File "E:\Anaconda\lib\urllib2.py", line 431, in open
    response = self._open(req, data)
  File "E:\Anaconda\lib\urllib2.py", line 449, in _open
    '_open', req)
  File "E:\Anaconda\lib\urllib2.py", line 409, in _call_chain
    result = func(*args)
  File "E:\Anaconda\lib\urllib2.py", line 1227, in http_open
    return self.do_open(httplib.HTTPConnection, req)
  File "E:\Anaconda\lib\urllib2.py", line 1197, in do_open
    raise URLError(err)
URLError: <urlopen error [Errno 10051] >
2015-07-24 01:39:48 [boto] ERROR: Unable to read instance data, giving up
2015-07-24 01:48:05 [boto] ERROR: Caught exception reading instance data
Traceback (most recent call last):
  File "E:\Anaconda\lib\site-packages\boto\utils.py", line 210, in retry_url
    r = opener.open(req, timeout=timeout)
  File "E:\Anaconda\lib\urllib2.py", line 431, in open
    response = self._open(req, data)
  File "E:\Anaconda\lib\urllib2.py", line 449, in _open
    '_open', req)
  File "E:\Anaconda\lib\urllib2.py", line 409, in _call_chain
    result = func(*args)
  File "E:\Anaconda\lib\urllib2.py", line 1227, in http_open
    return self.do_open(httplib.HTTPConnection, req)
  File "E:\Anaconda\lib\urllib2.py", line 1197, in do_open
    raise URLError(err)
URLError: <urlopen error [Errno 10051] >
2015-07-24 01:48:05 [boto] ERROR: Unable to read instance data, giving up
2015-07-24 01:53:08 [boto] ERROR: Caught exception reading instance data
Traceback (most recent call last):
  File "E:\Anaconda\lib\site-packages\boto\utils.py", line 210, in retry_url
    r = opener.open(req, timeout=timeout)
  File "E:\Anaconda\lib\urllib2.py", line 431, in open
    response = self._open(req, data)
  File "E:\Anaconda\lib\urllib2.py", line 449, in _open
    '_open', req)
  File "E:\Anaconda\lib\urllib2.py", line 409, in _call_chain
    result = func(*args)
  File "E:\Anaconda\lib\urllib2.py", line 1227, in http_open
    return self.do_open(httplib.HTTPConnection, req)
  File "E:\Anaconda\lib\urllib2.py", line 1197, in do_open
    raise URLError(err)
URLError: <urlopen error [Errno 10051] >
2015-07-24 01:53:08 [boto] ERROR: Unable to read instance data, giving up
2015-07-24 02:10:14 [scrapy] ERROR: Spider error processing <GET http://guba.sina.com.cn/?s=thread&tid=10124&bid=162> (referer: http://guba.sina.com.cn/?s=thread&tid=10124&bid=162)
Traceback (most recent call last):
  File "E:\Anaconda\lib\site-packages\scrapy\utils\defer.py", line 102, in iter_errback
    yield next(it)
  File "E:\Anaconda\lib\site-packages\scrapy\spidermiddlewares\offsite.py", line 28, in process_spider_output
    for x in result:
  File "E:\Anaconda\lib\site-packages\scrapy\spidermiddlewares\referer.py", line 22, in <genexpr>
    return (_set_referer(r) for r in result or ())
  File "E:\Anaconda\lib\site-packages\scrapy\spidermiddlewares\urllength.py", line 37, in <genexpr>
    return (r for r in result or () if _filter(r))
  File "E:\Anaconda\lib\site-packages\scrapy\spidermiddlewares\depth.py", line 54, in <genexpr>
    return (r for r in result or () if _filter(r))
  File "E:\liyi\stockAnaly\crawl\sinabbsCrawler\sinabbsCrawler\spiders\sinabbsSpider.py", line 276, in parseComment
    Date,Time = self.extracttime(text)
  File "E:\liyi\stockAnaly\crawl\sinabbsCrawler\sinabbsCrawler\spiders\sinabbsSpider.py", line 115, in extracttime
    return date(int(year),int(month),int(day)),time(0,0,0)
ValueError: day is out of range for month
2015-07-24 02:30:08 [boto] ERROR: Caught exception reading instance data
Traceback (most recent call last):
  File "E:\Anaconda\lib\site-packages\boto\utils.py", line 210, in retry_url
    r = opener.open(req, timeout=timeout)
  File "E:\Anaconda\lib\urllib2.py", line 431, in open
    response = self._open(req, data)
  File "E:\Anaconda\lib\urllib2.py", line 449, in _open
    '_open', req)
  File "E:\Anaconda\lib\urllib2.py", line 409, in _call_chain
    result = func(*args)
  File "E:\Anaconda\lib\urllib2.py", line 1227, in http_open
    return self.do_open(httplib.HTTPConnection, req)
  File "E:\Anaconda\lib\urllib2.py", line 1197, in do_open
    raise URLError(err)
URLError: <urlopen error [Errno 10051] >
2015-07-24 02:30:08 [boto] ERROR: Unable to read instance data, giving up
2015-07-24 02:37:02 [boto] ERROR: Caught exception reading instance data
Traceback (most recent call last):
  File "E:\Anaconda\lib\site-packages\boto\utils.py", line 210, in retry_url
    r = opener.open(req, timeout=timeout)
  File "E:\Anaconda\lib\urllib2.py", line 431, in open
    response = self._open(req, data)
  File "E:\Anaconda\lib\urllib2.py", line 449, in _open
    '_open', req)
  File "E:\Anaconda\lib\urllib2.py", line 409, in _call_chain
    result = func(*args)
  File "E:\Anaconda\lib\urllib2.py", line 1227, in http_open
    return self.do_open(httplib.HTTPConnection, req)
  File "E:\Anaconda\lib\urllib2.py", line 1197, in do_open
    raise URLError(err)
URLError: <urlopen error [Errno 10051] >
2015-07-24 02:37:02 [boto] ERROR: Unable to read instance data, giving up
2015-07-24 02:41:58 [boto] ERROR: Caught exception reading instance data
Traceback (most recent call last):
  File "E:\Anaconda\lib\site-packages\boto\utils.py", line 210, in retry_url
    r = opener.open(req, timeout=timeout)
  File "E:\Anaconda\lib\urllib2.py", line 431, in open
    response = self._open(req, data)
  File "E:\Anaconda\lib\urllib2.py", line 449, in _open
    '_open', req)
  File "E:\Anaconda\lib\urllib2.py", line 409, in _call_chain
    result = func(*args)
  File "E:\Anaconda\lib\urllib2.py", line 1227, in http_open
    return self.do_open(httplib.HTTPConnection, req)
  File "E:\Anaconda\lib\urllib2.py", line 1197, in do_open
    raise URLError(err)
URLError: <urlopen error [Errno 10051] >
2015-07-24 02:41:58 [boto] ERROR: Unable to read instance data, giving up
2015-07-24 02:48:03 [scrapy] ERROR: Spider error processing <GET http://guba.sina.com.cn/?s=thread&tid=8411&bid=1639> (referer: http://guba.sina.com.cn/?s=thread&tid=8411&bid=1639)
Traceback (most recent call last):
  File "E:\Anaconda\lib\site-packages\scrapy\utils\defer.py", line 102, in iter_errback
    yield next(it)
  File "E:\Anaconda\lib\site-packages\scrapy\spidermiddlewares\offsite.py", line 28, in process_spider_output
    for x in result:
  File "E:\Anaconda\lib\site-packages\scrapy\spidermiddlewares\referer.py", line 22, in <genexpr>
    return (_set_referer(r) for r in result or ())
  File "E:\Anaconda\lib\site-packages\scrapy\spidermiddlewares\urllength.py", line 37, in <genexpr>
    return (r for r in result or () if _filter(r))
  File "E:\Anaconda\lib\site-packages\scrapy\spidermiddlewares\depth.py", line 54, in <genexpr>
    return (r for r in result or () if _filter(r))
  File "E:\liyi\stockAnaly\crawl\sinabbsCrawler\sinabbsCrawler\spiders\sinabbsSpider.py", line 276, in parseComment
    Date,Time = self.extracttime(text)
  File "E:\liyi\stockAnaly\crawl\sinabbsCrawler\sinabbsCrawler\spiders\sinabbsSpider.py", line 115, in extracttime
    return date(int(year),int(month),int(day)),time(0,0,0)
ValueError: day is out of range for month
2015-07-24 02:54:14 [boto] ERROR: Caught exception reading instance data
Traceback (most recent call last):
  File "E:\Anaconda\lib\site-packages\boto\utils.py", line 210, in retry_url
    r = opener.open(req, timeout=timeout)
  File "E:\Anaconda\lib\urllib2.py", line 431, in open
    response = self._open(req, data)
  File "E:\Anaconda\lib\urllib2.py", line 449, in _open
    '_open', req)
  File "E:\Anaconda\lib\urllib2.py", line 409, in _call_chain
    result = func(*args)
  File "E:\Anaconda\lib\urllib2.py", line 1227, in http_open
    return self.do_open(httplib.HTTPConnection, req)
  File "E:\Anaconda\lib\urllib2.py", line 1197, in do_open
    raise URLError(err)
URLError: <urlopen error [Errno 10051] >
2015-07-24 02:54:14 [boto] ERROR: Unable to read instance data, giving up
2015-07-24 02:57:41 [boto] ERROR: Caught exception reading instance data
Traceback (most recent call last):
  File "E:\Anaconda\lib\site-packages\boto\utils.py", line 210, in retry_url
    r = opener.open(req, timeout=timeout)
  File "E:\Anaconda\lib\urllib2.py", line 431, in open
    response = self._open(req, data)
  File "E:\Anaconda\lib\urllib2.py", line 449, in _open
    '_open', req)
  File "E:\Anaconda\lib\urllib2.py", line 409, in _call_chain
    result = func(*args)
  File "E:\Anaconda\lib\urllib2.py", line 1227, in http_open
    return self.do_open(httplib.HTTPConnection, req)
  File "E:\Anaconda\lib\urllib2.py", line 1197, in do_open
    raise URLError(err)
URLError: <urlopen error [Errno 10051] >
2015-07-24 02:57:41 [boto] ERROR: Unable to read instance data, giving up
2015-07-24 03:02:49 [boto] ERROR: Caught exception reading instance data
Traceback (most recent call last):
  File "E:\Anaconda\lib\site-packages\boto\utils.py", line 210, in retry_url
    r = opener.open(req, timeout=timeout)
  File "E:\Anaconda\lib\urllib2.py", line 431, in open
    response = self._open(req, data)
  File "E:\Anaconda\lib\urllib2.py", line 449, in _open
    '_open', req)
  File "E:\Anaconda\lib\urllib2.py", line 409, in _call_chain
    result = func(*args)
  File "E:\Anaconda\lib\urllib2.py", line 1227, in http_open
    return self.do_open(httplib.HTTPConnection, req)
  File "E:\Anaconda\lib\urllib2.py", line 1197, in do_open
    raise URLError(err)
URLError: <urlopen error [Errno 10051] >
2015-07-24 03:02:49 [boto] ERROR: Unable to read instance data, giving up
2015-07-24 03:03:47 [boto] ERROR: Caught exception reading instance data
Traceback (most recent call last):
  File "E:\Anaconda\lib\site-packages\boto\utils.py", line 210, in retry_url
    r = opener.open(req, timeout=timeout)
  File "E:\Anaconda\lib\urllib2.py", line 431, in open
    response = self._open(req, data)
  File "E:\Anaconda\lib\urllib2.py", line 449, in _open
    '_open', req)
  File "E:\Anaconda\lib\urllib2.py", line 409, in _call_chain
    result = func(*args)
  File "E:\Anaconda\lib\urllib2.py", line 1227, in http_open
    return self.do_open(httplib.HTTPConnection, req)
  File "E:\Anaconda\lib\urllib2.py", line 1197, in do_open
    raise URLError(err)
URLError: <urlopen error [Errno 10051] >
2015-07-24 03:03:47 [boto] ERROR: Unable to read instance data, giving up
2015-07-24 03:18:52 [scrapy] ERROR: Spider error processing <GET http://guba.sina.com.cn/?s=thread&tid=23028&bid=515> (referer: http://guba.sina.com.cn/?s=thread&tid=23028&bid=515)
Traceback (most recent call last):
  File "E:\Anaconda\lib\site-packages\scrapy\utils\defer.py", line 102, in iter_errback
    yield next(it)
  File "E:\Anaconda\lib\site-packages\scrapy\spidermiddlewares\offsite.py", line 28, in process_spider_output
    for x in result:
  File "E:\Anaconda\lib\site-packages\scrapy\spidermiddlewares\referer.py", line 22, in <genexpr>
    return (_set_referer(r) for r in result or ())
  File "E:\Anaconda\lib\site-packages\scrapy\spidermiddlewares\urllength.py", line 37, in <genexpr>
    return (r for r in result or () if _filter(r))
  File "E:\Anaconda\lib\site-packages\scrapy\spidermiddlewares\depth.py", line 54, in <genexpr>
    return (r for r in result or () if _filter(r))
  File "E:\liyi\stockAnaly\crawl\sinabbsCrawler\sinabbsCrawler\spiders\sinabbsSpider.py", line 276, in parseComment
    Date,Time = self.extracttime(text)
  File "E:\liyi\stockAnaly\crawl\sinabbsCrawler\sinabbsCrawler\spiders\sinabbsSpider.py", line 115, in extracttime
    return date(int(year),int(month),int(day)),time(0,0,0)
ValueError: day is out of range for month
2015-07-24 03:19:15 [scrapy] ERROR: Spider error processing <GET http://guba.sina.com.cn/?s=thread&tid=22459&bid=515> (referer: http://guba.sina.com.cn/?s=thread&tid=22459&bid=515)
Traceback (most recent call last):
  File "E:\Anaconda\lib\site-packages\scrapy\utils\defer.py", line 102, in iter_errback
    yield next(it)
  File "E:\Anaconda\lib\site-packages\scrapy\spidermiddlewares\offsite.py", line 28, in process_spider_output
    for x in result:
  File "E:\Anaconda\lib\site-packages\scrapy\spidermiddlewares\referer.py", line 22, in <genexpr>
    return (_set_referer(r) for r in result or ())
  File "E:\Anaconda\lib\site-packages\scrapy\spidermiddlewares\urllength.py", line 37, in <genexpr>
    return (r for r in result or () if _filter(r))
  File "E:\Anaconda\lib\site-packages\scrapy\spidermiddlewares\depth.py", line 54, in <genexpr>
    return (r for r in result or () if _filter(r))
  File "E:\liyi\stockAnaly\crawl\sinabbsCrawler\sinabbsCrawler\spiders\sinabbsSpider.py", line 276, in parseComment
    Date,Time = self.extracttime(text)
  File "E:\liyi\stockAnaly\crawl\sinabbsCrawler\sinabbsCrawler\spiders\sinabbsSpider.py", line 115, in extracttime
    return date(int(year),int(month),int(day)),time(0,0,0)
ValueError: day is out of range for month
2015-07-24 03:19:27 [scrapy] ERROR: Spider error processing <GET http://guba.sina.com.cn/?s=thread&tid=23150&bid=515> (referer: http://guba.sina.com.cn/?s=thread&tid=23150&bid=515)
Traceback (most recent call last):
  File "E:\Anaconda\lib\site-packages\scrapy\utils\defer.py", line 102, in iter_errback
    yield next(it)
  File "E:\Anaconda\lib\site-packages\scrapy\spidermiddlewares\offsite.py", line 28, in process_spider_output
    for x in result:
  File "E:\Anaconda\lib\site-packages\scrapy\spidermiddlewares\referer.py", line 22, in <genexpr>
    return (_set_referer(r) for r in result or ())
  File "E:\Anaconda\lib\site-packages\scrapy\spidermiddlewares\urllength.py", line 37, in <genexpr>
    return (r for r in result or () if _filter(r))
  File "E:\Anaconda\lib\site-packages\scrapy\spidermiddlewares\depth.py", line 54, in <genexpr>
    return (r for r in result or () if _filter(r))
  File "E:\liyi\stockAnaly\crawl\sinabbsCrawler\sinabbsCrawler\spiders\sinabbsSpider.py", line 276, in parseComment
    Date,Time = self.extracttime(text)
  File "E:\liyi\stockAnaly\crawl\sinabbsCrawler\sinabbsCrawler\spiders\sinabbsSpider.py", line 115, in extracttime
    return date(int(year),int(month),int(day)),time(0,0,0)
ValueError: day is out of range for month
2015-07-24 03:19:28 [scrapy] ERROR: Spider error processing <GET http://guba.sina.com.cn/?s=thread&tid=23145&bid=515> (referer: http://guba.sina.com.cn/?s=thread&tid=23145&bid=515)
Traceback (most recent call last):
  File "E:\Anaconda\lib\site-packages\scrapy\utils\defer.py", line 102, in iter_errback
    yield next(it)
  File "E:\Anaconda\lib\site-packages\scrapy\spidermiddlewares\offsite.py", line 28, in process_spider_output
    for x in result:
  File "E:\Anaconda\lib\site-packages\scrapy\spidermiddlewares\referer.py", line 22, in <genexpr>
    return (_set_referer(r) for r in result or ())
  File "E:\Anaconda\lib\site-packages\scrapy\spidermiddlewares\urllength.py", line 37, in <genexpr>
    return (r for r in result or () if _filter(r))
  File "E:\Anaconda\lib\site-packages\scrapy\spidermiddlewares\depth.py", line 54, in <genexpr>
    return (r for r in result or () if _filter(r))
  File "E:\liyi\stockAnaly\crawl\sinabbsCrawler\sinabbsCrawler\spiders\sinabbsSpider.py", line 276, in parseComment
    Date,Time = self.extracttime(text)
  File "E:\liyi\stockAnaly\crawl\sinabbsCrawler\sinabbsCrawler\spiders\sinabbsSpider.py", line 115, in extracttime
    return date(int(year),int(month),int(day)),time(0,0,0)
ValueError: day is out of range for month
2015-07-24 03:19:30 [scrapy] ERROR: Spider error processing <GET http://guba.sina.com.cn/?s=thread&tid=21041&bid=515> (referer: http://guba.sina.com.cn/?s=thread&tid=21041&bid=515)
Traceback (most recent call last):
  File "E:\Anaconda\lib\site-packages\scrapy\utils\defer.py", line 102, in iter_errback
    yield next(it)
  File "E:\Anaconda\lib\site-packages\scrapy\spidermiddlewares\offsite.py", line 28, in process_spider_output
    for x in result:
  File "E:\Anaconda\lib\site-packages\scrapy\spidermiddlewares\referer.py", line 22, in <genexpr>
    return (_set_referer(r) for r in result or ())
  File "E:\Anaconda\lib\site-packages\scrapy\spidermiddlewares\urllength.py", line 37, in <genexpr>
    return (r for r in result or () if _filter(r))
  File "E:\Anaconda\lib\site-packages\scrapy\spidermiddlewares\depth.py", line 54, in <genexpr>
    return (r for r in result or () if _filter(r))
  File "E:\liyi\stockAnaly\crawl\sinabbsCrawler\sinabbsCrawler\spiders\sinabbsSpider.py", line 276, in parseComment
    Date,Time = self.extracttime(text)
  File "E:\liyi\stockAnaly\crawl\sinabbsCrawler\sinabbsCrawler\spiders\sinabbsSpider.py", line 115, in extracttime
    return date(int(year),int(month),int(day)),time(0,0,0)
ValueError: day is out of range for month
2015-07-24 03:30:24 [scrapy] ERROR: Spider error processing <GET http://guba.sina.com.cn/?s=thread&tid=23050&bid=515&page=5> (referer: http://guba.sina.com.cn/?s=thread&tid=23050&bid=515&page=4)
Traceback (most recent call last):
  File "E:\Anaconda\lib\site-packages\scrapy\utils\defer.py", line 102, in iter_errback
    yield next(it)
  File "E:\Anaconda\lib\site-packages\scrapy\spidermiddlewares\offsite.py", line 28, in process_spider_output
    for x in result:
  File "E:\Anaconda\lib\site-packages\scrapy\spidermiddlewares\referer.py", line 22, in <genexpr>
    return (_set_referer(r) for r in result or ())
  File "E:\Anaconda\lib\site-packages\scrapy\spidermiddlewares\urllength.py", line 37, in <genexpr>
    return (r for r in result or () if _filter(r))
  File "E:\Anaconda\lib\site-packages\scrapy\spidermiddlewares\depth.py", line 54, in <genexpr>
    return (r for r in result or () if _filter(r))
  File "E:\liyi\stockAnaly\crawl\sinabbsCrawler\sinabbsCrawler\spiders\sinabbsSpider.py", line 276, in parseComment
    Date,Time = self.extracttime(text)
  File "E:\liyi\stockAnaly\crawl\sinabbsCrawler\sinabbsCrawler\spiders\sinabbsSpider.py", line 115, in extracttime
    return date(int(year),int(month),int(day)),time(0,0,0)
ValueError: day is out of range for month
2015-07-24 03:39:28 [boto] ERROR: Caught exception reading instance data
Traceback (most recent call last):
  File "E:\Anaconda\lib\site-packages\boto\utils.py", line 210, in retry_url
    r = opener.open(req, timeout=timeout)
  File "E:\Anaconda\lib\urllib2.py", line 431, in open
    response = self._open(req, data)
  File "E:\Anaconda\lib\urllib2.py", line 449, in _open
    '_open', req)
  File "E:\Anaconda\lib\urllib2.py", line 409, in _call_chain
    result = func(*args)
  File "E:\Anaconda\lib\urllib2.py", line 1227, in http_open
    return self.do_open(httplib.HTTPConnection, req)
  File "E:\Anaconda\lib\urllib2.py", line 1197, in do_open
    raise URLError(err)
URLError: <urlopen error [Errno 10051] >
2015-07-24 03:39:28 [boto] ERROR: Unable to read instance data, giving up
2015-07-24 03:44:56 [boto] ERROR: Caught exception reading instance data
Traceback (most recent call last):
  File "E:\Anaconda\lib\site-packages\boto\utils.py", line 210, in retry_url
    r = opener.open(req, timeout=timeout)
  File "E:\Anaconda\lib\urllib2.py", line 431, in open
    response = self._open(req, data)
  File "E:\Anaconda\lib\urllib2.py", line 449, in _open
    '_open', req)
  File "E:\Anaconda\lib\urllib2.py", line 409, in _call_chain
    result = func(*args)
  File "E:\Anaconda\lib\urllib2.py", line 1227, in http_open
    return self.do_open(httplib.HTTPConnection, req)
  File "E:\Anaconda\lib\urllib2.py", line 1197, in do_open
    raise URLError(err)
URLError: <urlopen error [Errno 10051] >
2015-07-24 03:44:56 [boto] ERROR: Unable to read instance data, giving up
2015-07-24 04:22:14 [scrapy] ERROR: Spider error processing <GET http://guba.sina.com.cn/?s=thread&tid=215&bid=44> (referer: http://guba.sina.com.cn/?s=thread&tid=215&bid=44)
Traceback (most recent call last):
  File "E:\Anaconda\lib\site-packages\scrapy\utils\defer.py", line 102, in iter_errback
    yield next(it)
  File "E:\Anaconda\lib\site-packages\scrapy\spidermiddlewares\offsite.py", line 28, in process_spider_output
    for x in result:
  File "E:\Anaconda\lib\site-packages\scrapy\spidermiddlewares\referer.py", line 22, in <genexpr>
    return (_set_referer(r) for r in result or ())
  File "E:\Anaconda\lib\site-packages\scrapy\spidermiddlewares\urllength.py", line 37, in <genexpr>
    return (r for r in result or () if _filter(r))
  File "E:\Anaconda\lib\site-packages\scrapy\spidermiddlewares\depth.py", line 54, in <genexpr>
    return (r for r in result or () if _filter(r))
  File "E:\liyi\stockAnaly\crawl\sinabbsCrawler\sinabbsCrawler\spiders\sinabbsSpider.py", line 276, in parseComment
    Date,Time = self.extracttime(text)
  File "E:\liyi\stockAnaly\crawl\sinabbsCrawler\sinabbsCrawler\spiders\sinabbsSpider.py", line 115, in extracttime
    return date(int(year),int(month),int(day)),time(0,0,0)
ValueError: day is out of range for month
2015-07-24 04:22:14 [scrapy] ERROR: Spider error processing <GET http://guba.sina.com.cn/?s=thread&tid=224&bid=44> (referer: http://guba.sina.com.cn/?s=thread&tid=224&bid=44)
Traceback (most recent call last):
  File "E:\Anaconda\lib\site-packages\scrapy\utils\defer.py", line 102, in iter_errback
    yield next(it)
  File "E:\Anaconda\lib\site-packages\scrapy\spidermiddlewares\offsite.py", line 28, in process_spider_output
    for x in result:
  File "E:\Anaconda\lib\site-packages\scrapy\spidermiddlewares\referer.py", line 22, in <genexpr>
    return (_set_referer(r) for r in result or ())
  File "E:\Anaconda\lib\site-packages\scrapy\spidermiddlewares\urllength.py", line 37, in <genexpr>
    return (r for r in result or () if _filter(r))
  File "E:\Anaconda\lib\site-packages\scrapy\spidermiddlewares\depth.py", line 54, in <genexpr>
    return (r for r in result or () if _filter(r))
  File "E:\liyi\stockAnaly\crawl\sinabbsCrawler\sinabbsCrawler\spiders\sinabbsSpider.py", line 276, in parseComment
    Date,Time = self.extracttime(text)
  File "E:\liyi\stockAnaly\crawl\sinabbsCrawler\sinabbsCrawler\spiders\sinabbsSpider.py", line 115, in extracttime
    return date(int(year),int(month),int(day)),time(0,0,0)
ValueError: day is out of range for month
2015-07-24 04:27:32 [scrapy] ERROR: Spider error processing <GET http://guba.sina.com.cn/?s=thread&tid=15423&bid=44> (referer: http://guba.sina.com.cn/?s=thread&tid=15423&bid=44)
Traceback (most recent call last):
  File "E:\Anaconda\lib\site-packages\scrapy\utils\defer.py", line 102, in iter_errback
    yield next(it)
  File "E:\Anaconda\lib\site-packages\scrapy\spidermiddlewares\offsite.py", line 28, in process_spider_output
    for x in result:
  File "E:\Anaconda\lib\site-packages\scrapy\spidermiddlewares\referer.py", line 22, in <genexpr>
    return (_set_referer(r) for r in result or ())
  File "E:\Anaconda\lib\site-packages\scrapy\spidermiddlewares\urllength.py", line 37, in <genexpr>
    return (r for r in result or () if _filter(r))
  File "E:\Anaconda\lib\site-packages\scrapy\spidermiddlewares\depth.py", line 54, in <genexpr>
    return (r for r in result or () if _filter(r))
  File "E:\liyi\stockAnaly\crawl\sinabbsCrawler\sinabbsCrawler\spiders\sinabbsSpider.py", line 276, in parseComment
    Date,Time = self.extracttime(text)
  File "E:\liyi\stockAnaly\crawl\sinabbsCrawler\sinabbsCrawler\spiders\sinabbsSpider.py", line 115, in extracttime
    return date(int(year),int(month),int(day)),time(0,0,0)
ValueError: day is out of range for month
2015-07-24 04:53:54 [boto] ERROR: Caught exception reading instance data
Traceback (most recent call last):
  File "E:\Anaconda\lib\site-packages\boto\utils.py", line 210, in retry_url
    r = opener.open(req, timeout=timeout)
  File "E:\Anaconda\lib\urllib2.py", line 431, in open
    response = self._open(req, data)
  File "E:\Anaconda\lib\urllib2.py", line 449, in _open
    '_open', req)
  File "E:\Anaconda\lib\urllib2.py", line 409, in _call_chain
    result = func(*args)
  File "E:\Anaconda\lib\urllib2.py", line 1227, in http_open
    return self.do_open(httplib.HTTPConnection, req)
  File "E:\Anaconda\lib\urllib2.py", line 1197, in do_open
    raise URLError(err)
URLError: <urlopen error [Errno 10051] >
2015-07-24 04:53:54 [boto] ERROR: Unable to read instance data, giving up
2015-07-24 04:59:30 [scrapy] ERROR: Spider error processing <GET http://guba.sina.com.cn/?s=thread&tid=8691&bid=101&page=2> (referer: http://guba.sina.com.cn/?s=thread&tid=8691&bid=101)
Traceback (most recent call last):
  File "E:\Anaconda\lib\site-packages\scrapy\utils\defer.py", line 102, in iter_errback
    yield next(it)
  File "E:\Anaconda\lib\site-packages\scrapy\spidermiddlewares\offsite.py", line 28, in process_spider_output
    for x in result:
  File "E:\Anaconda\lib\site-packages\scrapy\spidermiddlewares\referer.py", line 22, in <genexpr>
    return (_set_referer(r) for r in result or ())
  File "E:\Anaconda\lib\site-packages\scrapy\spidermiddlewares\urllength.py", line 37, in <genexpr>
    return (r for r in result or () if _filter(r))
  File "E:\Anaconda\lib\site-packages\scrapy\spidermiddlewares\depth.py", line 54, in <genexpr>
    return (r for r in result or () if _filter(r))
  File "E:\liyi\stockAnaly\crawl\sinabbsCrawler\sinabbsCrawler\spiders\sinabbsSpider.py", line 276, in parseComment
    Date,Time = self.extracttime(text)
  File "E:\liyi\stockAnaly\crawl\sinabbsCrawler\sinabbsCrawler\spiders\sinabbsSpider.py", line 115, in extracttime
    return date(int(year),int(month),int(day)),time(0,0,0)
ValueError: day is out of range for month
2015-07-24 05:00:11 [scrapy] ERROR: Spider error processing <GET http://guba.sina.com.cn/?s=thread&tid=9137&bid=101> (referer: http://guba.sina.com.cn/?s=thread&tid=9137&bid=101)
Traceback (most recent call last):
  File "E:\Anaconda\lib\site-packages\scrapy\utils\defer.py", line 102, in iter_errback
    yield next(it)
  File "E:\Anaconda\lib\site-packages\scrapy\spidermiddlewares\offsite.py", line 28, in process_spider_output
    for x in result:
  File "E:\Anaconda\lib\site-packages\scrapy\spidermiddlewares\referer.py", line 22, in <genexpr>
    return (_set_referer(r) for r in result or ())
  File "E:\Anaconda\lib\site-packages\scrapy\spidermiddlewares\urllength.py", line 37, in <genexpr>
    return (r for r in result or () if _filter(r))
  File "E:\Anaconda\lib\site-packages\scrapy\spidermiddlewares\depth.py", line 54, in <genexpr>
    return (r for r in result or () if _filter(r))
  File "E:\liyi\stockAnaly\crawl\sinabbsCrawler\sinabbsCrawler\spiders\sinabbsSpider.py", line 276, in parseComment
    Date,Time = self.extracttime(text)
  File "E:\liyi\stockAnaly\crawl\sinabbsCrawler\sinabbsCrawler\spiders\sinabbsSpider.py", line 115, in extracttime
    return date(int(year),int(month),int(day)),time(0,0,0)
ValueError: day is out of range for month
2015-07-24 05:02:33 [scrapy] ERROR: Spider error processing <GET http://guba.sina.com.cn/?s=thread&tid=9188&bid=101> (referer: http://guba.sina.com.cn/?s=thread&tid=9188&bid=101)
Traceback (most recent call last):
  File "E:\Anaconda\lib\site-packages\scrapy\utils\defer.py", line 102, in iter_errback
    yield next(it)
  File "E:\Anaconda\lib\site-packages\scrapy\spidermiddlewares\offsite.py", line 28, in process_spider_output
    for x in result:
  File "E:\Anaconda\lib\site-packages\scrapy\spidermiddlewares\referer.py", line 22, in <genexpr>
    return (_set_referer(r) for r in result or ())
  File "E:\Anaconda\lib\site-packages\scrapy\spidermiddlewares\urllength.py", line 37, in <genexpr>
    return (r for r in result or () if _filter(r))
  File "E:\Anaconda\lib\site-packages\scrapy\spidermiddlewares\depth.py", line 54, in <genexpr>
    return (r for r in result or () if _filter(r))
  File "E:\liyi\stockAnaly\crawl\sinabbsCrawler\sinabbsCrawler\spiders\sinabbsSpider.py", line 276, in parseComment
    Date,Time = self.extracttime(text)
  File "E:\liyi\stockAnaly\crawl\sinabbsCrawler\sinabbsCrawler\spiders\sinabbsSpider.py", line 115, in extracttime
    return date(int(year),int(month),int(day)),time(0,0,0)
ValueError: day is out of range for month
2015-07-24 05:02:34 [scrapy] ERROR: Spider error processing <GET http://guba.sina.com.cn/?s=thread&tid=9191&bid=101> (referer: http://guba.sina.com.cn/?s=thread&tid=9191&bid=101)
Traceback (most recent call last):
  File "E:\Anaconda\lib\site-packages\scrapy\utils\defer.py", line 102, in iter_errback
    yield next(it)
  File "E:\Anaconda\lib\site-packages\scrapy\spidermiddlewares\offsite.py", line 28, in process_spider_output
    for x in result:
  File "E:\Anaconda\lib\site-packages\scrapy\spidermiddlewares\referer.py", line 22, in <genexpr>
    return (_set_referer(r) for r in result or ())
  File "E:\Anaconda\lib\site-packages\scrapy\spidermiddlewares\urllength.py", line 37, in <genexpr>
    return (r for r in result or () if _filter(r))
  File "E:\Anaconda\lib\site-packages\scrapy\spidermiddlewares\depth.py", line 54, in <genexpr>
    return (r for r in result or () if _filter(r))
  File "E:\liyi\stockAnaly\crawl\sinabbsCrawler\sinabbsCrawler\spiders\sinabbsSpider.py", line 276, in parseComment
    Date,Time = self.extracttime(text)
  File "E:\liyi\stockAnaly\crawl\sinabbsCrawler\sinabbsCrawler\spiders\sinabbsSpider.py", line 115, in extracttime
    return date(int(year),int(month),int(day)),time(0,0,0)
ValueError: day is out of range for month
2015-07-24 05:09:04 [boto] ERROR: Caught exception reading instance data
Traceback (most recent call last):
  File "E:\Anaconda\lib\site-packages\boto\utils.py", line 210, in retry_url
    r = opener.open(req, timeout=timeout)
  File "E:\Anaconda\lib\urllib2.py", line 431, in open
    response = self._open(req, data)
  File "E:\Anaconda\lib\urllib2.py", line 449, in _open
    '_open', req)
  File "E:\Anaconda\lib\urllib2.py", line 409, in _call_chain
    result = func(*args)
  File "E:\Anaconda\lib\urllib2.py", line 1227, in http_open
    return self.do_open(httplib.HTTPConnection, req)
  File "E:\Anaconda\lib\urllib2.py", line 1197, in do_open
    raise URLError(err)
URLError: <urlopen error [Errno 10051] >
2015-07-24 05:09:04 [boto] ERROR: Unable to read instance data, giving up
2015-07-24 05:16:10 [scrapy] ERROR: Spider error processing <GET http://guba.sina.com.cn/?s=thread&tid=8676&bid=1919> (referer: http://guba.sina.com.cn/?s=thread&tid=8676&bid=1919)
Traceback (most recent call last):
  File "E:\Anaconda\lib\site-packages\scrapy\utils\defer.py", line 102, in iter_errback
    yield next(it)
  File "E:\Anaconda\lib\site-packages\scrapy\spidermiddlewares\offsite.py", line 28, in process_spider_output
    for x in result:
  File "E:\Anaconda\lib\site-packages\scrapy\spidermiddlewares\referer.py", line 22, in <genexpr>
    return (_set_referer(r) for r in result or ())
  File "E:\Anaconda\lib\site-packages\scrapy\spidermiddlewares\urllength.py", line 37, in <genexpr>
    return (r for r in result or () if _filter(r))
  File "E:\Anaconda\lib\site-packages\scrapy\spidermiddlewares\depth.py", line 54, in <genexpr>
    return (r for r in result or () if _filter(r))
  File "E:\liyi\stockAnaly\crawl\sinabbsCrawler\sinabbsCrawler\spiders\sinabbsSpider.py", line 276, in parseComment
    Date,Time = self.extracttime(text)
  File "E:\liyi\stockAnaly\crawl\sinabbsCrawler\sinabbsCrawler\spiders\sinabbsSpider.py", line 115, in extracttime
    return date(int(year),int(month),int(day)),time(0,0,0)
ValueError: day is out of range for month
2015-07-24 05:16:26 [scrapy] ERROR: Spider error processing <GET http://guba.sina.com.cn/?s=thread&tid=6008&bid=1919> (referer: http://guba.sina.com.cn/?s=thread&tid=6008&bid=1919)
Traceback (most recent call last):
  File "E:\Anaconda\lib\site-packages\scrapy\utils\defer.py", line 102, in iter_errback
    yield next(it)
  File "E:\Anaconda\lib\site-packages\scrapy\spidermiddlewares\offsite.py", line 28, in process_spider_output
    for x in result:
  File "E:\Anaconda\lib\site-packages\scrapy\spidermiddlewares\referer.py", line 22, in <genexpr>
    return (_set_referer(r) for r in result or ())
  File "E:\Anaconda\lib\site-packages\scrapy\spidermiddlewares\urllength.py", line 37, in <genexpr>
    return (r for r in result or () if _filter(r))
  File "E:\Anaconda\lib\site-packages\scrapy\spidermiddlewares\depth.py", line 54, in <genexpr>
    return (r for r in result or () if _filter(r))
  File "E:\liyi\stockAnaly\crawl\sinabbsCrawler\sinabbsCrawler\spiders\sinabbsSpider.py", line 276, in parseComment
    Date,Time = self.extracttime(text)
  File "E:\liyi\stockAnaly\crawl\sinabbsCrawler\sinabbsCrawler\spiders\sinabbsSpider.py", line 115, in extracttime
    return date(int(year),int(month),int(day)),time(0,0,0)
ValueError: day is out of range for month
2015-07-24 05:17:00 [scrapy] ERROR: Spider error processing <GET http://guba.sina.com.cn/?s=thread&tid=8322&bid=1919&page=3> (referer: http://guba.sina.com.cn/?s=thread&tid=8322&bid=1919&page=2)
Traceback (most recent call last):
  File "E:\Anaconda\lib\site-packages\scrapy\utils\defer.py", line 102, in iter_errback
    yield next(it)
  File "E:\Anaconda\lib\site-packages\scrapy\spidermiddlewares\offsite.py", line 28, in process_spider_output
    for x in result:
  File "E:\Anaconda\lib\site-packages\scrapy\spidermiddlewares\referer.py", line 22, in <genexpr>
    return (_set_referer(r) for r in result or ())
  File "E:\Anaconda\lib\site-packages\scrapy\spidermiddlewares\urllength.py", line 37, in <genexpr>
    return (r for r in result or () if _filter(r))
  File "E:\Anaconda\lib\site-packages\scrapy\spidermiddlewares\depth.py", line 54, in <genexpr>
    return (r for r in result or () if _filter(r))
  File "E:\liyi\stockAnaly\crawl\sinabbsCrawler\sinabbsCrawler\spiders\sinabbsSpider.py", line 276, in parseComment
    Date,Time = self.extracttime(text)
  File "E:\liyi\stockAnaly\crawl\sinabbsCrawler\sinabbsCrawler\spiders\sinabbsSpider.py", line 115, in extracttime
    return date(int(year),int(month),int(day)),time(0,0,0)
ValueError: day is out of range for month
2015-07-24 05:24:53 [boto] ERROR: Caught exception reading instance data
Traceback (most recent call last):
  File "E:\Anaconda\lib\site-packages\boto\utils.py", line 210, in retry_url
    r = opener.open(req, timeout=timeout)
  File "E:\Anaconda\lib\urllib2.py", line 431, in open
    response = self._open(req, data)
  File "E:\Anaconda\lib\urllib2.py", line 449, in _open
    '_open', req)
  File "E:\Anaconda\lib\urllib2.py", line 409, in _call_chain
    result = func(*args)
  File "E:\Anaconda\lib\urllib2.py", line 1227, in http_open
    return self.do_open(httplib.HTTPConnection, req)
  File "E:\Anaconda\lib\urllib2.py", line 1197, in do_open
    raise URLError(err)
URLError: <urlopen error [Errno 10051] >
2015-07-24 05:24:53 [boto] ERROR: Unable to read instance data, giving up
2015-07-24 05:32:52 [boto] ERROR: Caught exception reading instance data
Traceback (most recent call last):
  File "E:\Anaconda\lib\site-packages\boto\utils.py", line 210, in retry_url
    r = opener.open(req, timeout=timeout)
  File "E:\Anaconda\lib\urllib2.py", line 431, in open
    response = self._open(req, data)
  File "E:\Anaconda\lib\urllib2.py", line 449, in _open
    '_open', req)
  File "E:\Anaconda\lib\urllib2.py", line 409, in _call_chain
    result = func(*args)
  File "E:\Anaconda\lib\urllib2.py", line 1227, in http_open
    return self.do_open(httplib.HTTPConnection, req)
  File "E:\Anaconda\lib\urllib2.py", line 1197, in do_open
    raise URLError(err)
URLError: <urlopen error [Errno 10051] >
2015-07-24 05:32:52 [boto] ERROR: Unable to read instance data, giving up
2015-07-24 05:41:27 [boto] ERROR: Caught exception reading instance data
Traceback (most recent call last):
  File "E:\Anaconda\lib\site-packages\boto\utils.py", line 210, in retry_url
    r = opener.open(req, timeout=timeout)
  File "E:\Anaconda\lib\urllib2.py", line 431, in open
    response = self._open(req, data)
  File "E:\Anaconda\lib\urllib2.py", line 449, in _open
    '_open', req)
  File "E:\Anaconda\lib\urllib2.py", line 409, in _call_chain
    result = func(*args)
  File "E:\Anaconda\lib\urllib2.py", line 1227, in http_open
    return self.do_open(httplib.HTTPConnection, req)
  File "E:\Anaconda\lib\urllib2.py", line 1197, in do_open
    raise URLError(err)
URLError: <urlopen error [Errno 10051] >
2015-07-24 05:41:27 [boto] ERROR: Unable to read instance data, giving up
2015-07-24 05:58:50 [boto] ERROR: Caught exception reading instance data
Traceback (most recent call last):
  File "E:\Anaconda\lib\site-packages\boto\utils.py", line 210, in retry_url
    r = opener.open(req, timeout=timeout)
  File "E:\Anaconda\lib\urllib2.py", line 431, in open
    response = self._open(req, data)
  File "E:\Anaconda\lib\urllib2.py", line 449, in _open
    '_open', req)
  File "E:\Anaconda\lib\urllib2.py", line 409, in _call_chain
    result = func(*args)
  File "E:\Anaconda\lib\urllib2.py", line 1227, in http_open
    return self.do_open(httplib.HTTPConnection, req)
  File "E:\Anaconda\lib\urllib2.py", line 1197, in do_open
    raise URLError(err)
URLError: <urlopen error [Errno 10051] >
2015-07-24 05:58:50 [boto] ERROR: Unable to read instance data, giving up
2015-07-24 07:02:11 [boto] ERROR: Caught exception reading instance data
Traceback (most recent call last):
  File "E:\Anaconda\lib\site-packages\boto\utils.py", line 210, in retry_url
    r = opener.open(req, timeout=timeout)
  File "E:\Anaconda\lib\urllib2.py", line 431, in open
    response = self._open(req, data)
  File "E:\Anaconda\lib\urllib2.py", line 449, in _open
    '_open', req)
  File "E:\Anaconda\lib\urllib2.py", line 409, in _call_chain
    result = func(*args)
  File "E:\Anaconda\lib\urllib2.py", line 1227, in http_open
    return self.do_open(httplib.HTTPConnection, req)
  File "E:\Anaconda\lib\urllib2.py", line 1197, in do_open
    raise URLError(err)
URLError: <urlopen error [Errno 10051] >
2015-07-24 07:02:11 [boto] ERROR: Unable to read instance data, giving up
2015-07-24 07:11:41 [boto] ERROR: Caught exception reading instance data
Traceback (most recent call last):
  File "E:\Anaconda\lib\site-packages\boto\utils.py", line 210, in retry_url
    r = opener.open(req, timeout=timeout)
  File "E:\Anaconda\lib\urllib2.py", line 431, in open
    response = self._open(req, data)
  File "E:\Anaconda\lib\urllib2.py", line 449, in _open
    '_open', req)
  File "E:\Anaconda\lib\urllib2.py", line 409, in _call_chain
    result = func(*args)
  File "E:\Anaconda\lib\urllib2.py", line 1227, in http_open
    return self.do_open(httplib.HTTPConnection, req)
  File "E:\Anaconda\lib\urllib2.py", line 1197, in do_open
    raise URLError(err)
URLError: <urlopen error [Errno 10051] >
2015-07-24 07:11:41 [boto] ERROR: Unable to read instance data, giving up
2015-07-24 07:28:30 [boto] ERROR: Caught exception reading instance data
Traceback (most recent call last):
  File "E:\Anaconda\lib\site-packages\boto\utils.py", line 210, in retry_url
    r = opener.open(req, timeout=timeout)
  File "E:\Anaconda\lib\urllib2.py", line 431, in open
    response = self._open(req, data)
  File "E:\Anaconda\lib\urllib2.py", line 449, in _open
    '_open', req)
  File "E:\Anaconda\lib\urllib2.py", line 409, in _call_chain
    result = func(*args)
  File "E:\Anaconda\lib\urllib2.py", line 1227, in http_open
    return self.do_open(httplib.HTTPConnection, req)
  File "E:\Anaconda\lib\urllib2.py", line 1197, in do_open
    raise URLError(err)
URLError: <urlopen error [Errno 10051] >
2015-07-24 07:28:30 [boto] ERROR: Unable to read instance data, giving up
2015-07-24 07:42:49 [scrapy] ERROR: Spider error processing <GET http://guba.sina.com.cn/?s=thread&tid=1074&bid=18&page=3> (referer: http://guba.sina.com.cn/?s=thread&tid=1074&bid=18&page=2)
Traceback (most recent call last):
  File "E:\Anaconda\lib\site-packages\scrapy\utils\defer.py", line 102, in iter_errback
    yield next(it)
  File "E:\Anaconda\lib\site-packages\scrapy\spidermiddlewares\offsite.py", line 28, in process_spider_output
    for x in result:
  File "E:\Anaconda\lib\site-packages\scrapy\spidermiddlewares\referer.py", line 22, in <genexpr>
    return (_set_referer(r) for r in result or ())
  File "E:\Anaconda\lib\site-packages\scrapy\spidermiddlewares\urllength.py", line 37, in <genexpr>
    return (r for r in result or () if _filter(r))
  File "E:\Anaconda\lib\site-packages\scrapy\spidermiddlewares\depth.py", line 54, in <genexpr>
    return (r for r in result or () if _filter(r))
  File "E:\liyi\stockAnaly\crawl\sinabbsCrawler\sinabbsCrawler\spiders\sinabbsSpider.py", line 276, in parseComment
    Date,Time = self.extracttime(text)
  File "E:\liyi\stockAnaly\crawl\sinabbsCrawler\sinabbsCrawler\spiders\sinabbsSpider.py", line 115, in extracttime
    return date(int(year),int(month),int(day)),time(0,0,0)
ValueError: day is out of range for month
2015-07-24 07:42:53 [scrapy] ERROR: Spider error processing <GET http://guba.sina.com.cn/?s=thread&tid=249&bid=18> (referer: http://guba.sina.com.cn/?s=thread&tid=249&bid=18)
Traceback (most recent call last):
  File "E:\Anaconda\lib\site-packages\scrapy\utils\defer.py", line 102, in iter_errback
    yield next(it)
  File "E:\Anaconda\lib\site-packages\scrapy\spidermiddlewares\offsite.py", line 28, in process_spider_output
    for x in result:
  File "E:\Anaconda\lib\site-packages\scrapy\spidermiddlewares\referer.py", line 22, in <genexpr>
    return (_set_referer(r) for r in result or ())
  File "E:\Anaconda\lib\site-packages\scrapy\spidermiddlewares\urllength.py", line 37, in <genexpr>
    return (r for r in result or () if _filter(r))
  File "E:\Anaconda\lib\site-packages\scrapy\spidermiddlewares\depth.py", line 54, in <genexpr>
    return (r for r in result or () if _filter(r))
  File "E:\liyi\stockAnaly\crawl\sinabbsCrawler\sinabbsCrawler\spiders\sinabbsSpider.py", line 276, in parseComment
    Date,Time = self.extracttime(text)
  File "E:\liyi\stockAnaly\crawl\sinabbsCrawler\sinabbsCrawler\spiders\sinabbsSpider.py", line 115, in extracttime
    return date(int(year),int(month),int(day)),time(0,0,0)
ValueError: day is out of range for month
2015-07-24 07:42:53 [scrapy] ERROR: Spider error processing <GET http://guba.sina.com.cn/?s=thread&tid=226&bid=18> (referer: http://guba.sina.com.cn/?s=thread&tid=226&bid=18)
Traceback (most recent call last):
  File "E:\Anaconda\lib\site-packages\scrapy\utils\defer.py", line 102, in iter_errback
    yield next(it)
  File "E:\Anaconda\lib\site-packages\scrapy\spidermiddlewares\offsite.py", line 28, in process_spider_output
    for x in result:
  File "E:\Anaconda\lib\site-packages\scrapy\spidermiddlewares\referer.py", line 22, in <genexpr>
    return (_set_referer(r) for r in result or ())
  File "E:\Anaconda\lib\site-packages\scrapy\spidermiddlewares\urllength.py", line 37, in <genexpr>
    return (r for r in result or () if _filter(r))
  File "E:\Anaconda\lib\site-packages\scrapy\spidermiddlewares\depth.py", line 54, in <genexpr>
    return (r for r in result or () if _filter(r))
  File "E:\liyi\stockAnaly\crawl\sinabbsCrawler\sinabbsCrawler\spiders\sinabbsSpider.py", line 276, in parseComment
    Date,Time = self.extracttime(text)
  File "E:\liyi\stockAnaly\crawl\sinabbsCrawler\sinabbsCrawler\spiders\sinabbsSpider.py", line 115, in extracttime
    return date(int(year),int(month),int(day)),time(0,0,0)
ValueError: day is out of range for month
2015-07-24 07:42:58 [scrapy] ERROR: Spider error processing <GET http://guba.sina.com.cn/?s=thread&tid=269&bid=18&page=2> (referer: http://guba.sina.com.cn/?s=thread&tid=269&bid=18)
Traceback (most recent call last):
  File "E:\Anaconda\lib\site-packages\scrapy\utils\defer.py", line 102, in iter_errback
    yield next(it)
  File "E:\Anaconda\lib\site-packages\scrapy\spidermiddlewares\offsite.py", line 28, in process_spider_output
    for x in result:
  File "E:\Anaconda\lib\site-packages\scrapy\spidermiddlewares\referer.py", line 22, in <genexpr>
    return (_set_referer(r) for r in result or ())
  File "E:\Anaconda\lib\site-packages\scrapy\spidermiddlewares\urllength.py", line 37, in <genexpr>
    return (r for r in result or () if _filter(r))
  File "E:\Anaconda\lib\site-packages\scrapy\spidermiddlewares\depth.py", line 54, in <genexpr>
    return (r for r in result or () if _filter(r))
  File "E:\liyi\stockAnaly\crawl\sinabbsCrawler\sinabbsCrawler\spiders\sinabbsSpider.py", line 276, in parseComment
    Date,Time = self.extracttime(text)
  File "E:\liyi\stockAnaly\crawl\sinabbsCrawler\sinabbsCrawler\spiders\sinabbsSpider.py", line 115, in extracttime
    return date(int(year),int(month),int(day)),time(0,0,0)
ValueError: day is out of range for month
2015-07-24 07:45:58 [scrapy] ERROR: Spider error processing <GET http://guba.sina.com.cn/?s=thread&tid=18930&bid=18> (referer: http://guba.sina.com.cn/?s=thread&tid=18930&bid=18)
Traceback (most recent call last):
  File "E:\Anaconda\lib\site-packages\scrapy\utils\defer.py", line 102, in iter_errback
    yield next(it)
  File "E:\Anaconda\lib\site-packages\scrapy\spidermiddlewares\offsite.py", line 28, in process_spider_output
    for x in result:
  File "E:\Anaconda\lib\site-packages\scrapy\spidermiddlewares\referer.py", line 22, in <genexpr>
    return (_set_referer(r) for r in result or ())
  File "E:\Anaconda\lib\site-packages\scrapy\spidermiddlewares\urllength.py", line 37, in <genexpr>
    return (r for r in result or () if _filter(r))
  File "E:\Anaconda\lib\site-packages\scrapy\spidermiddlewares\depth.py", line 54, in <genexpr>
    return (r for r in result or () if _filter(r))
  File "E:\liyi\stockAnaly\crawl\sinabbsCrawler\sinabbsCrawler\spiders\sinabbsSpider.py", line 276, in parseComment
    Date,Time = self.extracttime(text)
  File "E:\liyi\stockAnaly\crawl\sinabbsCrawler\sinabbsCrawler\spiders\sinabbsSpider.py", line 115, in extracttime
    return date(int(year),int(month),int(day)),time(0,0,0)
ValueError: day is out of range for month
2015-07-24 07:46:03 [scrapy] ERROR: Spider error processing <GET http://guba.sina.com.cn/?s=thread&tid=18646&bid=18> (referer: http://guba.sina.com.cn/?s=thread&tid=18646&bid=18)
Traceback (most recent call last):
  File "E:\Anaconda\lib\site-packages\scrapy\utils\defer.py", line 102, in iter_errback
    yield next(it)
  File "E:\Anaconda\lib\site-packages\scrapy\spidermiddlewares\offsite.py", line 28, in process_spider_output
    for x in result:
  File "E:\Anaconda\lib\site-packages\scrapy\spidermiddlewares\referer.py", line 22, in <genexpr>
    return (_set_referer(r) for r in result or ())
  File "E:\Anaconda\lib\site-packages\scrapy\spidermiddlewares\urllength.py", line 37, in <genexpr>
    return (r for r in result or () if _filter(r))
  File "E:\Anaconda\lib\site-packages\scrapy\spidermiddlewares\depth.py", line 54, in <genexpr>
    return (r for r in result or () if _filter(r))
  File "E:\liyi\stockAnaly\crawl\sinabbsCrawler\sinabbsCrawler\spiders\sinabbsSpider.py", line 276, in parseComment
    Date,Time = self.extracttime(text)
  File "E:\liyi\stockAnaly\crawl\sinabbsCrawler\sinabbsCrawler\spiders\sinabbsSpider.py", line 115, in extracttime
    return date(int(year),int(month),int(day)),time(0,0,0)
ValueError: day is out of range for month
2015-07-24 07:50:20 [scrapy] ERROR: Spider error processing <GET http://guba.sina.com.cn/?s=thread&tid=15164&bid=18&page=3> (referer: http://guba.sina.com.cn/?s=thread&tid=15164&bid=18&page=2)
Traceback (most recent call last):
  File "E:\Anaconda\lib\site-packages\scrapy\utils\defer.py", line 102, in iter_errback
    yield next(it)
  File "E:\Anaconda\lib\site-packages\scrapy\spidermiddlewares\offsite.py", line 28, in process_spider_output
    for x in result:
  File "E:\Anaconda\lib\site-packages\scrapy\spidermiddlewares\referer.py", line 22, in <genexpr>
    return (_set_referer(r) for r in result or ())
  File "E:\Anaconda\lib\site-packages\scrapy\spidermiddlewares\urllength.py", line 37, in <genexpr>
    return (r for r in result or () if _filter(r))
  File "E:\Anaconda\lib\site-packages\scrapy\spidermiddlewares\depth.py", line 54, in <genexpr>
    return (r for r in result or () if _filter(r))
  File "E:\liyi\stockAnaly\crawl\sinabbsCrawler\sinabbsCrawler\spiders\sinabbsSpider.py", line 276, in parseComment
    Date,Time = self.extracttime(text)
  File "E:\liyi\stockAnaly\crawl\sinabbsCrawler\sinabbsCrawler\spiders\sinabbsSpider.py", line 115, in extracttime
    return date(int(year),int(month),int(day)),time(0,0,0)
ValueError: day is out of range for month
2015-07-24 07:57:34 [boto] ERROR: Caught exception reading instance data
Traceback (most recent call last):
  File "E:\Anaconda\lib\site-packages\boto\utils.py", line 210, in retry_url
    r = opener.open(req, timeout=timeout)
  File "E:\Anaconda\lib\urllib2.py", line 431, in open
    response = self._open(req, data)
  File "E:\Anaconda\lib\urllib2.py", line 449, in _open
    '_open', req)
  File "E:\Anaconda\lib\urllib2.py", line 409, in _call_chain
    result = func(*args)
  File "E:\Anaconda\lib\urllib2.py", line 1227, in http_open
    return self.do_open(httplib.HTTPConnection, req)
  File "E:\Anaconda\lib\urllib2.py", line 1197, in do_open
    raise URLError(err)
URLError: <urlopen error [Errno 10051] >
2015-07-24 07:57:34 [boto] ERROR: Unable to read instance data, giving up
2015-07-24 08:08:12 [scrapy] ERROR: Spider error processing <GET http://guba.sina.com.cn/?s=thread&tid=20264&bid=1291&page=3> (referer: http://guba.sina.com.cn/?s=thread&tid=20264&bid=1291&page=2)
Traceback (most recent call last):
  File "E:\Anaconda\lib\site-packages\scrapy\utils\defer.py", line 102, in iter_errback
    yield next(it)
  File "E:\Anaconda\lib\site-packages\scrapy\spidermiddlewares\offsite.py", line 28, in process_spider_output
    for x in result:
  File "E:\Anaconda\lib\site-packages\scrapy\spidermiddlewares\referer.py", line 22, in <genexpr>
    return (_set_referer(r) for r in result or ())
  File "E:\Anaconda\lib\site-packages\scrapy\spidermiddlewares\urllength.py", line 37, in <genexpr>
    return (r for r in result or () if _filter(r))
  File "E:\Anaconda\lib\site-packages\scrapy\spidermiddlewares\depth.py", line 54, in <genexpr>
    return (r for r in result or () if _filter(r))
  File "E:\liyi\stockAnaly\crawl\sinabbsCrawler\sinabbsCrawler\spiders\sinabbsSpider.py", line 276, in parseComment
    Date,Time = self.extracttime(text)
  File "E:\liyi\stockAnaly\crawl\sinabbsCrawler\sinabbsCrawler\spiders\sinabbsSpider.py", line 115, in extracttime
    return date(int(year),int(month),int(day)),time(0,0,0)
ValueError: day is out of range for month
2015-07-24 08:14:08 [scrapy] ERROR: Spider error processing <GET http://guba.sina.com.cn/?s=thread&tid=20465&bid=1291> (referer: http://guba.sina.com.cn/?s=thread&tid=20465&bid=1291)
Traceback (most recent call last):
  File "E:\Anaconda\lib\site-packages\scrapy\utils\defer.py", line 102, in iter_errback
    yield next(it)
  File "E:\Anaconda\lib\site-packages\scrapy\spidermiddlewares\offsite.py", line 28, in process_spider_output
    for x in result:
  File "E:\Anaconda\lib\site-packages\scrapy\spidermiddlewares\referer.py", line 22, in <genexpr>
    return (_set_referer(r) for r in result or ())
  File "E:\Anaconda\lib\site-packages\scrapy\spidermiddlewares\urllength.py", line 37, in <genexpr>
    return (r for r in result or () if _filter(r))
  File "E:\Anaconda\lib\site-packages\scrapy\spidermiddlewares\depth.py", line 54, in <genexpr>
    return (r for r in result or () if _filter(r))
  File "E:\liyi\stockAnaly\crawl\sinabbsCrawler\sinabbsCrawler\spiders\sinabbsSpider.py", line 276, in parseComment
    Date,Time = self.extracttime(text)
  File "E:\liyi\stockAnaly\crawl\sinabbsCrawler\sinabbsCrawler\spiders\sinabbsSpider.py", line 115, in extracttime
    return date(int(year),int(month),int(day)),time(0,0,0)
ValueError: day is out of range for month
2015-07-24 08:14:09 [scrapy] ERROR: Spider error processing <GET http://guba.sina.com.cn/?s=thread&tid=10170&bid=1291> (referer: http://guba.sina.com.cn/?s=thread&tid=10170&bid=1291)
Traceback (most recent call last):
  File "E:\Anaconda\lib\site-packages\scrapy\utils\defer.py", line 102, in iter_errback
    yield next(it)
  File "E:\Anaconda\lib\site-packages\scrapy\spidermiddlewares\offsite.py", line 28, in process_spider_output
    for x in result:
  File "E:\Anaconda\lib\site-packages\scrapy\spidermiddlewares\referer.py", line 22, in <genexpr>
    return (_set_referer(r) for r in result or ())
  File "E:\Anaconda\lib\site-packages\scrapy\spidermiddlewares\urllength.py", line 37, in <genexpr>
    return (r for r in result or () if _filter(r))
  File "E:\Anaconda\lib\site-packages\scrapy\spidermiddlewares\depth.py", line 54, in <genexpr>
    return (r for r in result or () if _filter(r))
  File "E:\liyi\stockAnaly\crawl\sinabbsCrawler\sinabbsCrawler\spiders\sinabbsSpider.py", line 276, in parseComment
    Date,Time = self.extracttime(text)
  File "E:\liyi\stockAnaly\crawl\sinabbsCrawler\sinabbsCrawler\spiders\sinabbsSpider.py", line 115, in extracttime
    return date(int(year),int(month),int(day)),time(0,0,0)
ValueError: day is out of range for month
2015-07-24 08:20:09 [scrapy] ERROR: Spider error processing <GET http://guba.sina.com.cn/?s=thread&tid=18227&bid=1291&page=3> (referer: http://guba.sina.com.cn/?s=thread&tid=18227&bid=1291&page=2)
Traceback (most recent call last):
  File "E:\Anaconda\lib\site-packages\scrapy\utils\defer.py", line 102, in iter_errback
    yield next(it)
  File "E:\Anaconda\lib\site-packages\scrapy\spidermiddlewares\offsite.py", line 28, in process_spider_output
    for x in result:
  File "E:\Anaconda\lib\site-packages\scrapy\spidermiddlewares\referer.py", line 22, in <genexpr>
    return (_set_referer(r) for r in result or ())
  File "E:\Anaconda\lib\site-packages\scrapy\spidermiddlewares\urllength.py", line 37, in <genexpr>
    return (r for r in result or () if _filter(r))
  File "E:\Anaconda\lib\site-packages\scrapy\spidermiddlewares\depth.py", line 54, in <genexpr>
    return (r for r in result or () if _filter(r))
  File "E:\liyi\stockAnaly\crawl\sinabbsCrawler\sinabbsCrawler\spiders\sinabbsSpider.py", line 276, in parseComment
    Date,Time = self.extracttime(text)
  File "E:\liyi\stockAnaly\crawl\sinabbsCrawler\sinabbsCrawler\spiders\sinabbsSpider.py", line 115, in extracttime
    return date(int(year),int(month),int(day)),time(0,0,0)
ValueError: day is out of range for month
